Workbook

Sheet README
A1: Comcast Corporation DCF: read me first
A2: Comcast Corporation (NASDAQ: CMCSA). USD millions unless labelled. Blue = input, black = formula, green = link to another sheet. Same template as the Skydance model.
A4: What this is: a discounted cash flow model of Comcast on the same template as the Skydance model. The Versant cable networks spin closed January 2, 2026, so the base year is 2026 as now reported, without Versant.
A5: On June 29, 2026 Comcast announced a tax free spin of NBCUniversal and Sky, expected mid 2027. This model values the company as it is today, before that spin. Buybacks are suspended until it completes.
A6: Built October 24, 2026 from the Q3 2026 earnings release and 10-Q, the FY2025 10-K and market data as of October 23.
A7: Use: change blue cells on Inputs. Scenario switch in Inputs!C5. Not a recommendation.
A8: Biggest judgments: broadband subscriber losses against price, theme park softness, and whether 2.4 times leverage is the right capital structure for the discount rate.

Sheet Inputs
A1: Inputs and scenarios
A2: Comcast Corporation (NASDAQ: CMCSA). USD millions unless labelled. Blue = input, black = formula, green = link to another sheet. Same template as the Skydance model.
A4: Scenario selector
A5: Active scenario (1 Base, 2 Bear, 3 Bull) | C5: 1
A6: Active scenario name | C6: =CHOOSE(C5,"Base","Bear","Bull") -> Base
A8: Base year FY2026E (USD m) | B8: Value | I8: Source
A9: Revenue 2026E | B9: 120500 | I9: Estimate: 9M 2026 90,695 [1] plus a Q4 in line with Q3
A10: Adjusted EBITDA 2026E | B10: 35000 | I10: Estimate: 9M 2026 25,938 [1] plus a Q4 of about 9,000
A11: D and A FY2025 | B11: 16210 | I11: [2]
A12: Capex FY2025 | B12: 11750 | I12: [2]
A13: Free cash flow FY2025 | B13: 19235 | I13: [2]
A14: Free cash flow 9M 2026 | B14: 12716 | I14: [1]
A16: Revenue build, 2026E (USD m) | B16: Value | I16: Source
A17: Connectivity and Platforms | B17: 79000 | I17: 9M 2026 59,420 [1], annualized
A18: Content and Experiences, net of eliminations | B18: 41500 | I18: Media, Studios and Theme Parks less eliminations, 9M 2026 [1], annualized
A19: Total 2026E revenue | B19: =SUM(B17:B18) -> 120500 | I19: Check: 9M 2026 reported revenue 90,695 [1]
A21: Drivers by scenario | B21: 2026E | C21: 2027E | D21: 2028E | E21: 2029E | F21: 2030E | G21: 2031E | J21: Note
A22: Connectivity growth: Base | B22: -0.01 | C22: -0.01 | D22: -0.005 | E22: 0 | F22: 0 | G22: 0 | I22: Residential connectivity revenue fell about 1 to 2 percent in 2026 on broadband subscriber losses, offset by price [1].
A23: Connectivity growth: Bear | B23: -0.03 | C23: -0.03 | D23: -0.025 | E23: -0.02 | F23: -0.02 | G23: -0.02
A24: Connectivity growth: Bull | B24: 0.01 | C24: 0.01 | D24: 0.01 | E24: 0.01 | F24: 0.01 | G24: 0.01
A25: Connectivity growth: ACTIVE | B25: =CHOOSE($C$5,B22,B23,B24) -> -0.01 | C25: =CHOOSE($C$5,C22,C23,C24) -> -0.01 | D25: =CHOOSE($C$5,D22,D23,D24) -> -0.005 | E25: =CHOOSE($C$5,E22,E23,E24) -> 0 | F25: =CHOOSE($C$5,F22,F23,F24) -> 0 | G25: =CHOOSE($C$5,G22,G23,G24) -> 0
A27: Content and Experiences growth: Base | B27: 0.02 | C27: 0.02 | D27: 0.02 | E27: 0.02 | F27: 0.02 | G27: 0.02 | I27: Peacock turned profitable in Q2 and Q3 2026 with 48 million subscribers; theme parks EBITDA fell 17 percent in Q3 [1].
A28: Content and Experiences growth: Bear | B28: -0.01 | C28: -0.01 | D28: 0 | E28: 0 | F28: 0 | G28: 0
A29: Content and Experiences growth: Bull | B29: 0.04 | C29: 0.04 | D29: 0.03 | E29: 0.03 | F29: 0.03 | G29: 0.03
A30: Content and Experiences growth: ACTIVE | B30: =CHOOSE($C$5,B27,B28,B29) -> 0.02 | C30: =CHOOSE($C$5,C27,C28,C29) -> 0.02 | D30: =CHOOSE($C$5,D27,D28,D29) -> 0.02 | E30: =CHOOSE($C$5,E27,E28,E29) -> 0.02 | F30: =CHOOSE($C$5,F27,F28,F29) -> 0.02 | G30: =CHOOSE($C$5,G27,G28,G29) -> 0.02
A32: Underlying EBITDA margin: Base | B32: 0.29 | C32: 0.288 | D32: 0.286 | E32: 0.284 | F32: 0.282 | G32: 0.28 | I32: 9M 2026 adjusted EBITDA margin 28.6 percent [1].
A33: Underlying EBITDA margin: Bear | B33: 0.285 | C33: 0.278 | D33: 0.27 | E33: 0.262 | F33: 0.255 | G33: 0.25
A34: Underlying EBITDA margin: Bull | B34: 0.292 | C34: 0.294 | D34: 0.296 | E34: 0.298 | F34: 0.3 | G34: 0.3
A35: Underlying EBITDA margin: ACTIVE | B35: =CHOOSE($C$5,B32,B33,B34) -> 0.29 | C35: =CHOOSE($C$5,C32,C33,C34) -> 0.288 | D35: =CHOOSE($C$5,D32,D33,D34) -> 0.286 | E35: =CHOOSE($C$5,E32,E33,E34) -> 0.284 | F35: =CHOOSE($C$5,F32,F33,F34) -> 0.282 | G35: =CHOOSE($C$5,G32,G33,G34) -> 0.28
A37: Other EBITDA items: Base | B37: 0 | C37: 0 | D37: 0 | E37: 0 | F37: 0 | G37: 0 | I37: No synergy line.
A38: Other EBITDA items: Bear | B38: 0 | C38: 0 | D38: 0 | E38: 0 | F38: 0 | G38: 0
A39: Other EBITDA items: Bull | B39: 0 | C39: 0 | D39: 0 | E39: 0 | F39: 0 | G39: 0
A40: Other EBITDA items: ACTIVE | B40: =CHOOSE($C$5,B37,B38,B39) -> 0 | C40: =CHOOSE($C$5,C37,C38,C39) -> 0 | D40: =CHOOSE($C$5,D37,D38,D39) -> 0 | E40: =CHOOSE($C$5,E37,E38,E39) -> 0 | F40: =CHOOSE($C$5,F37,F38,F39) -> 0 | G40: =CHOOSE($C$5,G37,G38,G39) -> 0
A42: Stock based compensation: Base | B42: 1500 | C42: 1500 | D42: 1500 | E42: 1500 | F42: 1500 | G42: 1500 | I42: SBC 1,288 in FY2025 [2], 1,134 in 9M 2026 [1].
A43: Stock based compensation: Bear | B43: 1500 | C43: 1500 | D43: 1500 | E43: 1500 | F43: 1500 | G43: 1500
A44: Stock based compensation: Bull | B44: 1500 | C44: 1500 | D44: 1500 | E44: 1500 | F44: 1500 | G44: 1500
A45: Stock based compensation: ACTIVE | B45: =CHOOSE($C$5,B42,B43,B44) -> 1500 | C45: =CHOOSE($C$5,C42,C43,C44) -> 1500 | D45: =CHOOSE($C$5,D42,D43,D44) -> 1500 | E45: =CHOOSE($C$5,E42,E43,E44) -> 1500 | F45: =CHOOSE($C$5,F42,F43,F44) -> 1500 | G45: =CHOOSE($C$5,G42,G43,G44) -> 1500
A47: Cash restructuring and one offs: Base | B47: 500 | C47: 800 | D47: 300 | E47: 0 | F47: 0 | G47: 0 | I47: NBCUniversal and Sky separation costs through mid 2027. Analyst estimate.
A48: Cash restructuring and one offs: Bear | B48: 500 | C48: 1000 | D48: 500 | E48: 200 | F48: 0 | G48: 0
A49: Cash restructuring and one offs: Bull | B49: 500 | C49: 600 | D49: 200 | E49: 0 | F49: 0 | G49: 0
...

Sheet Historical
A1: Historical results
A2: Comcast Corporation (NASDAQ: CMCSA). USD millions unless labelled. Blue = input, black = formula, green = link to another sheet. Same template as the Skydance model.
A4: USD millions | B4: FY2024 | C4: FY2025 | D4: 9M 2026 | E4: Source
A5: Revenue, as reported, Versant inside through 2025 | B5: 123731 | C5: 123707 | D5: 90695 | E5: [2][1]
A6: Adjusted EBITDA | B6: 38069 | C6: 37384 | D6: 25938 | E6: [2][1]
A7: Connectivity and Platforms revenue | D7: 59420 | E7: [1]
A8: Connectivity and Platforms adjusted EBITDA | D8: 23462 | E8: [1]
A9: Media revenue | D9: 18330 | E9: [1]
A10: Studios revenue | D10: 9433 | E10: [1]
A11: Theme Parks revenue | D11: 7341 | E11: [1]
A12: Depreciation and amortization | B12: 14802 | C12: 16210 | D12: 11252 | E12: [2][1]
A13: Stock based compensation | C13: 1288 | D13: 1134 | E13: [2][1]
A14: Capital expenditures | B14: 12181 | C14: 11750 | D14: 8311 | E14: [2][1]
A15: Free cash flow | B15: 12543 | C15: 19235 | D15: 12716 | E15: [2][1]
A16: Net debt, period end | C16: 89456 | D16: 79770 | E16: derived [2][1]
A18: Full year 2024 and 2025 segment splits were not retrieved; 2026 quarters are on the new basis without Versant and, from Q2, without Sky Deutschland.

Sheet Forecast
A1: Forecast
A2: Comcast Corporation (NASDAQ: CMCSA). USD millions unless labelled. Blue = input, black = formula, green = link to another sheet. Same template as the Skydance model.
A4: USD millions | B4: 2026E | C4: 2027E | D4: 2028E | E4: 2029E | F4: 2030E | G4: 2031E | H4: Note
A5: Connectivity and Platforms revenue | B5: =Inputs!B17 -> 79000 | C5: =B5*(1+Inputs!C$25) -> 78210 | D5: =C5*(1+Inputs!D$25) -> 77818.95 | E5: =D5*(1+Inputs!E$25) -> 77818.95 | F5: =E5*(1+Inputs!F$25) -> 77818.95 | G5: =F5*(1+Inputs!G$25) -> 77818.95
A6: Content and Experiences, net of eliminations revenue | B6: =Inputs!B18 -> 41500 | C6: =B6*(1+Inputs!C$30) -> 42330 | D6: =C6*(1+Inputs!D$30) -> 43176.6 | E6: =D6*(1+Inputs!E$30) -> 44040.132 | F6: =E6*(1+Inputs!F$30) -> 44920.935 | G6: =F6*(1+Inputs!G$30) -> 45819.353
A7: Total revenue | B7: =SUM(B5:B6) -> 120500 | C7: =SUM(C5:C6) -> 120540 | D7: =SUM(D5:D6) -> 120995.55 | E7: =SUM(E5:E6) -> 121859.08 | F7: =SUM(F5:F6) -> 122739.88 | G7: =SUM(G5:G6) -> 123638.3
A8: Revenue growth | C8: =C7/B7-1 -> 0.00033195021 | D8: =D7/C7-1 -> 0.0037792434 | E8: =E7/D7-1 -> 0.0071368906 | F8: =F7/E7-1 -> 0.0072280426 | G8: =G7/F7-1 -> 0.0073196964
A10: Underlying EBITDA before other items | B10: =B7*Inputs!B$35 -> 34945 | C10: =C7*Inputs!C$35 -> 34715.52 | D10: =D7*Inputs!D$35 -> 34604.727 | E10: =E7*Inputs!E$35 -> 34607.979 | F10: =F7*Inputs!F$35 -> 34612.647 | G10: =G7*Inputs!G$35 -> 34618.725
A11: Other EBITDA items (synergies, cost programs) | B11: =Inputs!B$40 -> 0 | C11: =Inputs!C$40 -> 0 | D11: =Inputs!D$40 -> 0 | E11: =Inputs!E$40 -> 0 | F11: =Inputs!F$40 -> 0 | G11: =Inputs!G$40 -> 0
A12: Adjusted EBITDA | B12: =B10+B11 -> 34945 | C12: =C10+C11 -> 34715.52 | D12: =D10+D11 -> 34604.727 | E12: =E10+E11 -> 34607.979 | F12: =F10+F11 -> 34612.647 | G12: =G10+G11 -> 34618.725
A13: Adjusted EBITDA margin | B13: =B12/B7 -> 0.29 | C13: =C12/C7 -> 0.288 | D13: =D12/D7 -> 0.286 | E13: =E12/E7 -> 0.284 | F13: =F12/F7 -> 0.282 | G13: =G12/G7 -> 0.28
A14: Less stock based compensation | B14: =-Inputs!B$45 -> -1500 | C14: =-Inputs!C$45 -> -1500 | D14: =-Inputs!D$45 -> -1500 | E14: =-Inputs!E$45 -> -1500 | F14: =-Inputs!F$45 -> -1500 | G14: =-Inputs!G$45 -> -1500
A15: Less cash restructuring and integration | B15: =-Inputs!B$50 -> -500 | C15: =-Inputs!C$50 -> -800 | D15: =-Inputs!D$50 -> -300 | E15: =-Inputs!E$50 -> 0 | F15: =-Inputs!F$50 -> 0 | G15: =-Inputs!G$50 -> 0
A16: EBITDA after stock comp and one offs | B16: =B12+B14+B15 -> 32945 | C16: =C12+C14+C15 -> 32415.52 | D16: =D12+D14+D15 -> 32804.727 | E16: =E12+E14+E15 -> 33107.979 | F16: =F12+F14+F15 -> 33112.647 | G16: =G12+G14+G15 -> 33118.725
A17: Less tax depreciation and amortization | B17: =-Inputs!B$65 -> -16000 | C17: =-Inputs!C$65 -> -16000 | D17: =-Inputs!D$65 -> -16000 | E17: =-Inputs!E$65 -> -16000 | F17: =-Inputs!F$65 -> -16000 | G17: =-Inputs!G$65 -> -16000
A18: Taxable operating profit | B18: =B16+B17 -> 16945 | C18: =C16+C17 -> 16415.52 | D18: =D16+D17 -> 16804.727 | E18: =E16+E17 -> 17107.979 | F18: =F16+F17 -> 17112.647 | G18: =G16+G17 -> 17118.725
A19: Cash taxes | B19: =-MAX(0,B18)*Inputs!$B$76 -> -3897.35 | C19: =-MAX(0,C18)*Inputs!$B$76 -> -3775.5696 | D19: =-MAX(0,D18)*Inputs!$B$76 -> -3865.0873 | E19: =-MAX(0,E18)*Inputs!$B$76 -> -3934.8352 | F19: =-MAX(0,F18)*Inputs!$B$76 -> -3935.9089 | G19: =-MAX(0,G18)*Inputs!$B$76 -> -3937.3067
A20: Less capital expenditures | B20: =-B7*Inputs!B$55 -> -11447.5 | C20: =-C7*Inputs!C$55 -> -11451.3 | D20: =-D7*Inputs!D$55 -> -11494.577 | E20: =-E7*Inputs!E$55 -> -11576.613 | F20: =-F7*Inputs!F$55 -> -11660.289 | G20: =-G7*Inputs!G$55 -> -11745.639
A21: Less working capital and content investment | B21: =-B7*Inputs!B$60 -> -602.5 | C21: =-C7*Inputs!C$60 -> -602.7 | D21: =-D7*Inputs!D$60 -> -604.97775 | E21: =-E7*Inputs!E$60 -> -609.29541 | F21: =-F7*Inputs!F$60 -> -613.69942 | G21: =-G7*Inputs!G$60 -> -618.19152
A22: Unlevered free cash flow | B22: =B16+B19+B20+B21 -> 16997.65 | C22: =C16+C19+C20+C21 -> 16585.95 | D22: =D16+D19+D20+D21 -> 16840.085 | E22: =E16+E19+E20+E21 -> 16987.236 | F22: =F16+F19+F20+F21 -> 16902.75 | G22: =G16+G19+G20+G21 -> 16817.588
A23: Conversion, unlevered FCF over adjusted EBITDA | B23: =B22/B12 -> 0.4864115 | C23: =C22/C12 -> 0.47776759 | D23: =D22/D12 -> 0.48664117 | E23: =E22/E12 -> 0.49084738 | F23: =F22/F12 -> 0.48834028 | G23: =G22/G12 -> 0.48579455
A25: Comcast gives no numeric 2026 guidance on capex or FCF [1]. FY2025 FCF of 19,235 is after interest.

Sheet WACC
A1: Cost of capital
A2: Comcast Corporation (NASDAQ: CMCSA). USD millions unless labelled. Blue = input, black = formula, green = link to another sheet. Same template as the Skydance model.
A4: Input or step | B4: Value | C4: Basis
A5: Risk free rate, 10 year Treasury, October 22, 2026 | B5: 0.0495 | C5: Mortgage News Daily, 4.954 percent on October 22, 2026. Same in all five models.
A6: Equity risk premium | B6: 0.045 | C6: Analyst input, 4.5 percent in all five models.
A7: Unlevered beta | B7: 0.7 | C7: Quoted beta 0.67 [8] at about 1.0 debt to equity unlevers below 0.4, which is too low for a media and cable company. 0.70 is an analyst input, in line with cable peers.
A8: Market value of equity | B8: =Inputs!$B$68*Inputs!$B$69 -> 78264.04 | C8: Price times shares
A9: Net debt | B9: =Inputs!$B$70-Inputs!$B$71 -> 79770 | C9: Latest balance sheet
A10: Debt to equity | B10: =B9/B8 -> 1.019242
A11: Tax rate | B11: =Inputs!$B$76 -> 0.23
A12: Levered beta | B12: =B7*(1+(1-B11)*B10) -> 1.2493715 | C12: Hamada relevering
A13: Cost of equity | B13: =B5+B12*B6 -> 0.10572172 | C13: CAPM
A14: Pre tax cost of debt | B14: 0.05 | C14: Single A rated, under review for downgrade on the spin announcement [unverified]. Analyst input.
A15: After tax cost of debt | B15: =B14*(1-B11) -> 0.0385
A16: Weight of equity | B16: =B8/(B8+B9) -> 0.49523533 | C16: Market weights at the latest close
A17: Weight of debt | B17: =B9/(B8+B9) -> 0.50476467
A18: WACC | B18: =B16*B13+B17*B15 -> 0.071790569
A20: Net cash companies: when net debt is below zero the debt weight is zero and the WACC equals the cost of equity on the equity weight above 100 percent; the formulas handle that but read the weights.

Sheet DCF
A1: Discounted cash flow
A2: Comcast Corporation (NASDAQ: CMCSA). USD millions unless labelled. Blue = input, black = formula, green = link to another sheet. Same template as the Skydance model.
A4: USD millions | B4: 2026E | C4: 2027E | D4: 2028E | E4: 2029E | F4: 2030E | G4: 2031E | H4: Note
A5: Unlevered free cash flow | B5: =Forecast!B22 -> 16997.65 | C5: =Forecast!C22 -> 16585.95 | D5: =Forecast!D22 -> 16840.085 | E5: =Forecast!E22 -> 16987.236 | F5: =Forecast!F22 -> 16902.75 | G5: =Forecast!G22 -> 16817.588
A6: Fraction of year included | B6: =Inputs!$B$73 -> 0.19 | C6: 1 | D6: 1 | E6: 1 | F6: 1 | G6: 1
A7: Cash flow included | B7: =B5*B6 -> 3229.5535 | C7: =C5*C6 -> 16585.95 | D7: =D5*D6 -> 16840.085 | E7: =E5*E6 -> 16987.236 | F7: =F5*F6 -> 16902.75 | G7: =G5*G6 -> 16817.588
A8: Discount period, years from valuation date, mid year | B8: =B6/2 -> 0.095 | C8: =B6+1-0.5 -> 0.69 | D8: =B6+2-0.5 -> 1.69 | E8: =B6+3-0.5 -> 2.69 | F8: =B6+4-0.5 -> 3.69 | G8: =B6+5-0.5 -> 4.69
A9: Discount factor | B9: =1/(1+WACC!$B$18)^B8 -> 0.99343523 | C9: =1/(1+WACC!$B$18)^C8 -> 0.95328805 | D9: =1/(1+WACC!$B$18)^D8 -> 0.889435 | E9: =1/(1+WACC!$B$18)^E8 -> 0.82985896 | F9: =1/(1+WACC!$B$18)^F8 -> 0.77427343 | G9: =1/(1+WACC!$B$18)^G8 -> 0.72241112
A10: Present value | B10: =B7*B9 -> 3208.3522 | C10: =C7*C9 -> 15811.188 | D10: =D7*D9 -> 14978.161 | E10: =E7*E9 -> 14097.01 | F10: =F7*F9 -> 13087.35 | G10: =G7*G9 -> 12149.213
A12: Terminal value, perpetuity growth method
A13: Long term growth | B13: =Inputs!$B$74 -> 0.005
A14: Terminal year cash flow, grown one year | B14: =G5*(1+B13) -> 16901.676
A15: Terminal value at end of forecast | B15: =B14/(WACC!B18-B13) -> 253054.83
A16: Discount factor, end of forecast | B16: =1/(1+WACC!B18)^(B6+5) -> 0.69779758
A17: Present value of terminal value | B17: =B15*B16 -> 176581.05
A18: Implied exit multiple of final year EBITDA | B18: =B15/Forecast!G12 -> 7.3097674
A20: Terminal value, exit multiple method
A21: Exit multiple | B21: =Inputs!$B$75 -> 5.5
A22: Terminal value at end of forecast | B22: =B21*Forecast!G12 -> 190402.99
A23: Present value of terminal value | B23: =B22*B16 -> 132862.74
A24: Implied perpetuity growth | B24: =(B22*WACC!B18-G5)/(B22+G5) -> -0.015193709
A26: Enterprise value and bridge to equity | B26: Perpetuity | C26: Exit multiple | H26: Note
A27: Sum of present value of forecast cash flows | B27: =SUM(B10:G10) -> 73331.274 | C27: =B27 -> 73331.274
A28: Present value of terminal value | B28: =B17 -> 176581.05 | C28: =B23 -> 132862.74
A29: Enterprise value | B29: =B27+B28 -> 249912.32 | C29: =C27+C28 -> 206194.02
A30: Terminal value share of enterprise value | B30: =B28/B29 -> 0.70657199 | C30: =C28/C29 -> 0.6443579
A31: Less net debt | B31: =-WACC!B9 -> -79770 | C31: =B31 -> -79770
A32: Less noncontrolling interests and other claims | B32: =-Inputs!$B$72 -> 0 | C32: =B32 -> 0
A33: Equity value | B33: =B29+B31+B32 -> 170142.32 | C33: =C29+C31+C32 -> 126424.02
A34: Shares outstanding, millions | B34: =Inputs!$B$69 -> 3551 | C34: =B34 -> 3551
A35: Implied value per share | B35: =B33/B34 -> 47.913917 | C35: =C33/C34 -> 35.60237 | H35: Model output under stated assumptions, not a recommendation.
A36: Market price | B36: =Inputs!$B$68 -> 22.04 | C36: =B36 -> 22.04
A37: Model value over market price | B37: =B35/B36-1 -> 1.1739527 | C37: =C35/C36-1 -> 0.61535256
A38: Market enterprise value for reference | B38: =WACC!B8+WACC!B9+Inputs!$B$72 -> 158034.04
A39: Market EV to 2026E adjusted EBITDA | B39: =B38/Forecast!B12 -> 4.5223649
A40: Model EV to 2026E adjusted EBITDA | B40: =B29/Forecast!B12 -> 7.1515902 | C40: =C29/Forecast!B12 -> 5.9005299

Sheet Sensitivity
A1: Sensitivity of implied value per share
A2: Comcast Corporation (NASDAQ: CMCSA). USD millions unless labelled. Blue = input, black = formula, green = link to another sheet. Same template as the Skydance model.
A4: Perpetuity growth method: WACC down, long term growth across. Value per share, $.
A5: WACC \ growth | B5: -0.02 | C5: -0.01 | D5: 0 | E5: 0.005 | F5: 0.01
A6: 0.06 | B6: =((SUMPRODUCT(DCF!$B$7:$G$7/(1+$A6)^DCF!$B$8:$G$8)+DCF!$G$5*(1+B$5)/($A6-B$5)/(1+$A6)^(DCF!$B$6+5))+DCF!$B$31+DCF!$B$32)/DCF!$B$34 -> 41.632825 | C6: =((SUMPRODUCT(DCF!$B$7:$G$7/(1+$A6)^DCF!$B$8:$G$8)+DCF!$G$5*(1+C$5)/($A6-C$5)/(1+$A6)^(DCF!$B$6+5))+DCF!$B$31+DCF!$B$32)/DCF!$B$34 -> 48.257941 | D6: =((SUMPRODUCT(DCF!$B$7:$G$7/(1+$A6)^DCF!$B$8:$G$8)+DCF!$G$5*(1+D$5)/($A6-D$5)/(1+$A6)^(DCF!$B$6+5))+DCF!$B$31+DCF!$B$32)/DCF!$B$34 -> 57.091427 | E6: =((SUMPRODUCT(DCF!$B$7:$G$7/(1+$A6)^DCF!$B$8:$G$8)+DCF!$G$5*(1+E$5)/($A6-E$5)/(1+$A6)^(DCF!$B$6+5))+DCF!$B$31+DCF!$B$32)/DCF!$B$34 -> 62.712737 | F6: =((SUMPRODUCT(DCF!$B$7:$G$7/(1+$A6)^DCF!$B$8:$G$8)+DCF!$G$5*(1+F$5)/($A6-F$5)/(1+$A6)^(DCF!$B$6+5))+DCF!$B$31+DCF!$B$32)/DCF!$B$34 -> 69.458309
A7: 0.065 | B7: =((SUMPRODUCT(DCF!$B$7:$G$7/(1+$A7)^DCF!$B$8:$G$8)+DCF!$G$5*(1+B$5)/($A7-B$5)/(1+$A7)^(DCF!$B$6+5))+DCF!$B$31+DCF!$B$32)/DCF!$B$34 -> 37.891893 | C7: =((SUMPRODUCT(DCF!$B$7:$G$7/(1+$A7)^DCF!$B$8:$G$8)+DCF!$G$5*(1+C$5)/($A7-C$5)/(1+$A7)^(DCF!$B$6+5))+DCF!$B$31+DCF!$B$32)/DCF!$B$34 -> 43.597974 | D7: =((SUMPRODUCT(DCF!$B$7:$G$7/(1+$A7)^DCF!$B$8:$G$8)+DCF!$G$5*(1+D$5)/($A7-D$5)/(1+$A7)^(DCF!$B$6+5))+DCF!$B$31+DCF!$B$32)/DCF!$B$34 -> 51.059774 | E7: =((SUMPRODUCT(DCF!$B$7:$G$7/(1+$A7)^DCF!$B$8:$G$8)+DCF!$G$5*(1+E$5)/($A7-E$5)/(1+$A7)^(DCF!$B$6+5))+DCF!$B$31+DCF!$B$32)/DCF!$B$34 -> 55.723398 | F7: =((SUMPRODUCT(DCF!$B$7:$G$7/(1+$A7)^DCF!$B$8:$G$8)+DCF!$G$5*(1+F$5)/($A7-F$5)/(1+$A7)^(DCF!$B$6+5))+DCF!$B$31+DCF!$B$32)/DCF!$B$34 -> 61.234954
A8: 0.07 | B8: =((SUMPRODUCT(DCF!$B$7:$G$7/(1+$A8)^DCF!$B$8:$G$8)+DCF!$G$5*(1+B$5)/($A8-B$5)/(1+$A8)^(DCF!$B$6+5))+DCF!$B$31+DCF!$B$32)/DCF!$B$34 -> 34.570656 | C8: =((SUMPRODUCT(DCF!$B$7:$G$7/(1+$A8)^DCF!$B$8:$G$8)+DCF!$G$5*(1+C$5)/($A8-C$5)/(1+$A8)^(DCF!$B$6+5))+DCF!$B$31+DCF!$B$32)/DCF!$B$34 -> 39.52473 | D8: =((SUMPRODUCT(DCF!$B$7:$G$7/(1+$A8)^DCF!$B$8:$G$8)+DCF!$G$5*(1+D$5)/($A8-D$5)/(1+$A8)^(DCF!$B$6+5))+DCF!$B$31+DCF!$B$32)/DCF!$B$34 -> 45.894254 | E8: =((SUMPRODUCT(DCF!$B$7:$G$7/(1+$A8)^DCF!$B$8:$G$8)+DCF!$G$5*(1+E$5)/($A8-E$5)/(1+$A8)^(DCF!$B$6+5))+DCF!$B$31+DCF!$B$32)/DCF!$B$34 -> 49.813961 | F8: =((SUMPRODUCT(DCF!$B$7:$G$7/(1+$A8)^DCF!$B$8:$G$8)+DCF!$G$5*(1+F$5)/($A8-F$5)/(1+$A8)^(DCF!$B$6+5))+DCF!$B$31+DCF!$B$32)/DCF!$B$34 -> 54.386952
A9: 0.075 | B9: =((SUMPRODUCT(DCF!$B$7:$G$7/(1+$A9)^DCF!$B$8:$G$8)+DCF!$G$5*(1+B$5)/($A9-B$5)/(1+$A9)^(DCF!$B$6+5))+DCF!$B$31+DCF!$B$32)/DCF!$B$34 -> 31.60267 | C9: =((SUMPRODUCT(DCF!$B$7:$G$7/(1+$A9)^DCF!$B$8:$G$8)+DCF!$G$5*(1+C$5)/($A9-C$5)/(1+$A9)^(DCF!$B$6+5))+DCF!$B$31+DCF!$B$32)/DCF!$B$34 -> 35.934477 | D9: =((SUMPRODUCT(DCF!$B$7:$G$7/(1+$A9)^DCF!$B$8:$G$8)+DCF!$G$5*(1+D$5)/($A9-D$5)/(1+$A9)^(DCF!$B$6+5))+DCF!$B$31+DCF!$B$32)/DCF!$B$34 -> 41.421432 | E9: =((SUMPRODUCT(DCF!$B$7:$G$7/(1+$A9)^DCF!$B$8:$G$8)+DCF!$G$5*(1+E$5)/($A9-E$5)/(1+$A9)^(DCF!$B$6+5))+DCF!$B$31+DCF!$B$32)/DCF!$B$34 -> 44.752797 | F9: =((SUMPRODUCT(DCF!$B$7:$G$7/(1+$A9)^DCF!$B$8:$G$8)+DCF!$G$5*(1+F$5)/($A9-F$5)/(1+$A9)^(DCF!$B$6+5))+DCF!$B$31+DCF!$B$32)/DCF!$B$34 -> 48.59668
A10: 0.08 | B10: =((SUMPRODUCT(DCF!$B$7:$G$7/(1+$A10)^DCF!$B$8:$G$8)+DCF!$G$5*(1+B$5)/($A10-B$5)/(1+$A10)^(DCF!$B$6+5))+DCF!$B$31+DCF!$B$32)/DCF!$B$34 -> 28.93479 | C10: =((SUMPRODUCT(DCF!$B$7:$G$7/(1+$A10)^DCF!$B$8:$G$8)+DCF!$G$5*(1+C$5)/($A10-C$5)/(1+$A10)^(DCF!$B$6+5))+DCF!$B$31+DCF!$B$32)/DCF!$B$34 -> 32.746545 | D10: =((SUMPRODUCT(DCF!$B$7:$G$7/(1+$A10)^DCF!$B$8:$G$8)+DCF!$G$5*(1+D$5)/($A10-D$5)/(1+$A10)^(DCF!$B$6+5))+DCF!$B$31+DCF!$B$32)/DCF!$B$34 -> 37.511239 | E10: =((SUMPRODUCT(DCF!$B$7:$G$7/(1+$A10)^DCF!$B$8:$G$8)+DCF!$G$5*(1+E$5)/($A10-E$5)/(1+$A10)^(DCF!$B$6+5))+DCF!$B$31+DCF!$B$32)/DCF!$B$34 -> 40.370055 | F10: =((SUMPRODUCT(DCF!$B$7:$G$7/(1+$A10)^DCF!$B$8:$G$8)+DCF!$G$5*(1+F$5)/($A10-F$5)/(1+$A10)^(DCF!$B$6+5))+DCF!$B$31+DCF!$B$32)/DCF!$B$34 -> 43.637274
A11: 0.085 | B11: =((SUMPRODUCT(DCF!$B$7:$G$7/(1+$A11)^DCF!$B$8:$G$8)+DCF!$G$5*(1+B$5)/($A11-B$5)/(1+$A11)^(DCF!$B$6+5))+DCF!$B$31+DCF!$B$32)/DCF!$B$34 -> 26.523996 | C11: =((SUMPRODUCT(DCF!$B$7:$G$7/(1+$A11)^DCF!$B$8:$G$8)+DCF!$G$5*(1+C$5)/($A11-C$5)/(1+$A11)^(DCF!$B$6+5))+DCF!$B$31+DCF!$B$32)/DCF!$B$34 -> 29.897254 | D11: =((SUMPRODUCT(DCF!$B$7:$G$7/(1+$A11)^DCF!$B$8:$G$8)+DCF!$G$5*(1+D$5)/($A11-D$5)/(1+$A11)^(DCF!$B$6+5))+DCF!$B$31+DCF!$B$32)/DCF!$B$34 -> 34.064219 | E11: =((SUMPRODUCT(DCF!$B$7:$G$7/(1+$A11)^DCF!$B$8:$G$8)+DCF!$G$5*(1+E$5)/($A11-E$5)/(1+$A11)^(DCF!$B$6+5))+DCF!$B$31+DCF!$B$32)/DCF!$B$34 -> 36.538355 | F11: =((SUMPRODUCT(DCF!$B$7:$G$7/(1+$A11)^DCF!$B$8:$G$8)+DCF!$G$5*(1+F$5)/($A11-F$5)/(1+$A11)^(DCF!$B$6+5))+DCF!$B$31+DCF!$B$32)/DCF!$B$34 -> 39.342376
A12: 0.09 | B12: =((SUMPRODUCT(DCF!$B$7:$G$7/(1+$A12)^DCF!$B$8:$G$8)+DCF!$G$5*(1+B$5)/($A12-B$5)/(1+$A12)^(DCF!$B$6+5))+DCF!$B$31+DCF!$B$32)/DCF!$B$34 -> 24.3351 | C12: =((SUMPRODUCT(DCF!$B$7:$G$7/(1+$A12)^DCF!$B$8:$G$8)+DCF!$G$5*(1+C$5)/($A12-C$5)/(1+$A12)^(DCF!$B$6+5))+DCF!$B$31+DCF!$B$32)/DCF!$B$34 -> 27.335667 | D12: =((SUMPRODUCT(DCF!$B$7:$G$7/(1+$A12)^DCF!$B$8:$G$8)+DCF!$G$5*(1+D$5)/($A12-D$5)/(1+$A12)^(DCF!$B$6+5))+DCF!$B$31+DCF!$B$32)/DCF!$B$34 -> 31.003027 | E12: =((SUMPRODUCT(DCF!$B$7:$G$7/(1+$A12)^DCF!$B$8:$G$8)+DCF!$G$5*(1+E$5)/($A12-E$5)/(1+$A12)^(DCF!$B$6+5))+DCF!$B$31+DCF!$B$32)/DCF!$B$34 -> 33.160297 | F12: =((SUMPRODUCT(DCF!$B$7:$G$7/(1+$A12)^DCF!$B$8:$G$8)+DCF!$G$5*(1+F$5)/($A12-F$5)/(1+$A12)^(DCF!$B$6+5))+DCF!$B$31+DCF!$B$32)/DCF!$B$34 -> 35.587226
A15: Exit multiple method: WACC down, exit EV to EBITDA across. Value per share, $.
A16: WACC \ multiple | B16: 4 | C16: 4.5 | D16: 5 | E16: 5.5 | F16: 6
A17: 0.06 | B17: =((SUMPRODUCT(DCF!$B$7:$G$7/(1+$A17)^DCF!$B$8:$G$8)+B$16*Forecast!$G$12/(1+$A17)^(DCF!$B$6+5))+DCF!$B$31+DCF!$B$32)/DCF!$B$34 -> 27.576348 | C17: =((SUMPRODUCT(DCF!$B$7:$G$7/(1+$A17)^DCF!$B$8:$G$8)+C$16*Forecast!$G$12/(1+$A17)^(DCF!$B$6+5))+DCF!$B$31+DCF!$B$32)/DCF!$B$34 -> 31.178757 | D17: =((SUMPRODUCT(DCF!$B$7:$G$7/(1+$A17)^DCF!$B$8:$G$8)+D$16*Forecast!$G$12/(1+$A17)^(DCF!$B$6+5))+DCF!$B$31+DCF!$B$32)/DCF!$B$34 -> 34.781165 | E17: =((SUMPRODUCT(DCF!$B$7:$G$7/(1+$A17)^DCF!$B$8:$G$8)+E$16*Forecast!$G$12/(1+$A17)^(DCF!$B$6+5))+DCF!$B$31+DCF!$B$32)/DCF!$B$34 -> 38.383574 | F17: =((SUMPRODUCT(DCF!$B$7:$G$7/(1+$A17)^DCF!$B$8:$G$8)+F$16*Forecast!$G$12/(1+$A17)^(DCF!$B$6+5))+DCF!$B$31+DCF!$B$32)/DCF!$B$34 -> 41.985982
A18: 0.065 | B18: =((SUMPRODUCT(DCF!$B$7:$G$7/(1+$A18)^DCF!$B$8:$G$8)+B$16*Forecast!$G$12/(1+$A18)^(DCF!$B$6+5))+DCF!$B$31+DCF!$B$32)/DCF!$B$34 -> 26.635817 | C18: =((SUMPRODUCT(DCF!$B$7:$G$7/(1+$A18)^DCF!$B$8:$G$8)+C$16*Forecast!$G$12/(1+$A18)^(DCF!$B$6+5))+DCF!$B$31+DCF!$B$32)/DCF!$B$34 -> 30.151307 | D18: =((SUMPRODUCT(DCF!$B$7:$G$7/(1+$A18)^DCF!$B$8:$G$8)+D$16*Forecast!$G$12/(1+$A18)^(DCF!$B$6+5))+DCF!$B$31+DCF!$B$32)/DCF!$B$34 -> 33.666798 | E18: =((SUMPRODUCT(DCF!$B$7:$G$7/(1+$A18)^DCF!$B$8:$G$8)+E$16*Forecast!$G$12/(1+$A18)^(DCF!$B$6+5))+DCF!$B$31+DCF!$B$32)/DCF!$B$34 -> 37.182288 | F18: =((SUMPRODUCT(DCF!$B$7:$G$7/(1+$A18)^DCF!$B$8:$G$8)+F$16*Forecast!$G$12/(1+$A18)^(DCF!$B$6+5))+DCF!$B$31+DCF!$B$32)/DCF!$B$34 -> 40.697779
A19: 0.07 | B19: =((SUMPRODUCT(DCF!$B$7:$G$7/(1+$A19)^DCF!$B$8:$G$8)+B$16*Forecast!$G$12/(1+$A19)^(DCF!$B$6+5))+DCF!$B$31+DCF!$B$32)/DCF!$B$34 -> 25.720142 | C19: =((SUMPRODUCT(DCF!$B$7:$G$7/(1+$A19)^DCF!$B$8:$G$8)+C$16*Forecast!$G$12/(1+$A19)^(DCF!$B$6+5))+DCF!$B$31+DCF!$B$32)/DCF!$B$34 -> 29.151205 | D19: =((SUMPRODUCT(DCF!$B$7:$G$7/(1+$A19)^DCF!$B$8:$G$8)+D$16*Forecast!$G$12/(1+$A19)^(DCF!$B$6+5))+DCF!$B$31+DCF!$B$32)/DCF!$B$34 -> 32.582267 | E19: =((SUMPRODUCT(DCF!$B$7:$G$7/(1+$A19)^DCF!$B$8:$G$8)+E$16*Forecast!$G$12/(1+$A19)^(DCF!$B$6+5))+DCF!$B$31+DCF!$B$32)/DCF!$B$34 -> 36.013329 | F19: =((SUMPRODUCT(DCF!$B$7:$G$7/(1+$A19)^DCF!$B$8:$G$8)+F$16*Forecast!$G$12/(1+$A19)^(DCF!$B$6+5))+DCF!$B$31+DCF!$B$32)/DCF!$B$34 -> 39.444391
A20: 0.075 | B20: =((SUMPRODUCT(DCF!$B$7:$G$7/(1+$A20)^DCF!$B$8:$G$8)+B$16*Forecast!$G$12/(1+$A20)^(DCF!$B$6+5))+DCF!$B$31+DCF!$B$32)/DCF!$B$34 -> 24.828536 | C20: =((SUMPRODUCT(DCF!$B$7:$G$7/(1+$A20)^DCF!$B$8:$G$8)+C$16*Forecast!$G$12/(1+$A20)^(DCF!$B$6+5))+DCF!$B$31+DCF!$B$32)/DCF!$B$34 -> 28.177577 | D20: =((SUMPRODUCT(DCF!$B$7:$G$7/(1+$A20)^DCF!$B$8:$G$8)+D$16*Forecast!$G$12/(1+$A20)^(DCF!$B$6+5))+DCF!$B$31+DCF!$B$32)/DCF!$B$34 -> 31.526618 | E20: =((SUMPRODUCT(DCF!$B$7:$G$7/(1+$A20)^DCF!$B$8:$G$8)+E$16*Forecast!$G$12/(1+$A20)^(DCF!$B$6+5))+DCF!$B$31+DCF!$B$32)/DCF!$B$34 -> 34.875659 | F20: =((SUMPRODUCT(DCF!$B$7:$G$7/(1+$A20)^DCF!$B$8:$G$8)+F$16*Forecast!$G$12/(1+$A20)^(DCF!$B$6+5))+DCF!$B$31+DCF!$B$32)/DCF!$B$34 -> 38.2247
A21: 0.08 | B21: =((SUMPRODUCT(DCF!$B$7:$G$7/(1+$A21)^DCF!$B$8:$G$8)+B$16*Forecast!$G$12/(1+$A21)^(DCF!$B$6+5))+DCF!$B$31+DCF!$B$32)/DCF!$B$34 -> 23.960238 | C21: =((SUMPRODUCT(DCF!$B$7:$G$7/(1+$A21)^DCF!$B$8:$G$8)+C$16*Forecast!$G$12/(1+$A21)^(DCF!$B$6+5))+DCF!$B$31+DCF!$B$32)/DCF!$B$34 -> 27.229586 | D21: =((SUMPRODUCT(DCF!$B$7:$G$7/(1+$A21)^DCF!$B$8:$G$8)+D$16*Forecast!$G$12/(1+$A21)^(DCF!$B$6+5))+DCF!$B$31+DCF!$B$32)/DCF!$B$34 -> 30.498933 | E21: =((SUMPRODUCT(DCF!$B$7:$G$7/(1+$A21)^DCF!$B$8:$G$8)+E$16*Forecast!$G$12/(1+$A21)^(DCF!$B$6+5))+DCF!$B$31+DCF!$B$32)/DCF!$B$34 -> 33.768281 | F21: =((SUMPRODUCT(DCF!$B$7:$G$7/(1+$A21)^DCF!$B$8:$G$8)+F$16*Forecast!$G$12/(1+$A21)^(DCF!$B$6+5))+DCF!$B$31+DCF!$B$32)/DCF!$B$34 -> 37.037629
A22: 0.085 | B22: =((SUMPRODUCT(DCF!$B$7:$G$7/(1+$A22)^DCF!$B$8:$G$8)+B$16*Forecast!$G$12/(1+$A22)^(DCF!$B$6+5))+DCF!$B$31+DCF!$B$32)/DCF!$B$34 -> 23.114514 | C22: =((SUMPRODUCT(DCF!$B$7:$G$7/(1+$A22)^DCF!$B$8:$G$8)+C$16*Forecast!$G$12/(1+$A22)^(DCF!$B$6+5))+DCF!$B$31+DCF!$B$32)/DCF!$B$34 -> 26.30642 | D22: =((SUMPRODUCT(DCF!$B$7:$G$7/(1+$A22)^DCF!$B$8:$G$8)+D$16*Forecast!$G$12/(1+$A22)^(DCF!$B$6+5))+DCF!$B$31+DCF!$B$32)/DCF!$B$34 -> 29.498326 | E22: =((SUMPRODUCT(DCF!$B$7:$G$7/(1+$A22)^DCF!$B$8:$G$8)+E$16*Forecast!$G$12/(1+$A22)^(DCF!$B$6+5))+DCF!$B$31+DCF!$B$32)/DCF!$B$34 -> 32.690232 | F22: =((SUMPRODUCT(DCF!$B$7:$G$7/(1+$A22)^DCF!$B$8:$G$8)+F$16*Forecast!$G$12/(1+$A22)^(DCF!$B$6+5))+DCF!$B$31+DCF!$B$32)/DCF!$B$34 -> 35.882137
A23: 0.09 | B23: =((SUMPRODUCT(DCF!$B$7:$G$7/(1+$A23)^DCF!$B$8:$G$8)+B$16*Forecast!$G$12/(1+$A23)^(DCF!$B$6+5))+DCF!$B$31+DCF!$B$32)/DCF!$B$34 -> 22.290659 | C23: =((SUMPRODUCT(DCF!$B$7:$G$7/(1+$A23)^DCF!$B$8:$G$8)+C$16*Forecast!$G$12/(1+$A23)^(DCF!$B$6+5))+DCF!$B$31+DCF!$B$32)/DCF!$B$34 -> 25.407301 | D23: =((SUMPRODUCT(DCF!$B$7:$G$7/(1+$A23)^DCF!$B$8:$G$8)+D$16*Forecast!$G$12/(1+$A23)^(DCF!$B$6+5))+DCF!$B$31+DCF!$B$32)/DCF!$B$34 -> 28.523943 | E23: =((SUMPRODUCT(DCF!$B$7:$G$7/(1+$A23)^DCF!$B$8:$G$8)+E$16*Forecast!$G$12/(1+$A23)^(DCF!$B$6+5))+DCF!$B$31+DCF!$B$32)/DCF!$B$34 -> 31.640585 | F23: =((SUMPRODUCT(DCF!$B$7:$G$7/(1+$A23)^DCF!$B$8:$G$8)+F$16*Forecast!$G$12/(1+$A23)^(DCF!$B$6+5))+DCF!$B$31+DCF!$B$32)/DCF!$B$34 -> 34.757226
A26: Scenario summary, values as built. Change Inputs!C5 to see each scenario live.
A27: Scenario | B27: 2031E EBITDA | C27: $ per share, perpetuity | D27: $ per share, exit
A28: Base | B28: 34618.725 | C28: 47.913917 | D28: 35.60237
A29: Bear | B29: 27851.364 | C29: 29.132335 | D29: 23.932662
A30: Bull | B30: 39482.026 | C30: 62.19074 | D30: 44.084054
A32: Market price for reference | B32: =Inputs!$B$68 -> 22.04
A33: No free consensus or target range was found for Comcast in this pass.

Sheet Sources
A1: Sources
A2: Comcast Corporation (NASDAQ: CMCSA). USD millions unless labelled. Blue = input, black = formula, green = link to another sheet. Same template as the Skydance model.
A4: # | B4: Source
A5: 1 | B5: Comcast Q3 2026 earnings release and Form 10-Q, quarter ended September 30, 2026. sec.gov
A6: 2 | B6: Comcast Form 10-K for fiscal 2025. sec.gov
A7: 3 | B7: Comcast Q4 2025 earnings release, January 2026. cmcsa.com
A8: 4 | B8: Comcast Q1 2026 and Q2 2026 earnings releases. cmcsa.com
A9: 5 | B9: Comcast press release on the NBCUniversal and Sky separation, June 29, 2026.
A10: 6 | B10: Versant Media Group spin completion, January 2, 2026.
A11: 7 | B11: Comcast balance sheet, December 31, 2025, Form 10-K. sec.gov
A12: 8 | B12: Yahoo Finance, CMCSA quote and statistics, October 23, 2026.
A13: 9 | B13: Mortgage News Daily, 10 year Treasury yield through October 22, 2026.
A14: 10 | B14: Press coverage of the Sky Deutschland sale, May 2026.
A15: 11 | B15: Press coverage of Moody's review for downgrade, June 2026.
A16: 12 | B16: Comcast Peacock subscriber disclosures, Q2 and Q3 2026.
... A18: 14 | B18: Comcast dividend declaration, 2026.
B20: Analyst inputs with no source are labelled as such on the Inputs and WACC sheets. Nothing in this workbook comes from a Bloomberg Terminal or from any employer.
