Workbook

Sheet README
A1: Skydance Corporation DCF: read me first
A2: Skydance Corporation (NYSE: SKYD), pro forma for Warner Bros. Discovery. USD millions unless labelled. Blue = input, black = formula, green = link to another sheet.
A4: What this is: a discounted cash flow model of Skydance Corporation, the company formed when Paramount Skydance closed its purchase of Warner Bros. Discovery on October 6, 2026.
A5: Basis: pro forma combined. Paramount Skydance's filed results plus Warner Bros. Discovery's filed results, with the merger financing and share count from the October 2026 8-Ks.
A6: Built: October 24, 2026, from public SEC filings, company releases, a Debtwire credit report and market data as of the October 23, 2026 close. No Bloomberg data and nothing from any employer.
A8: How to use it: change blue cells on the Inputs sheet only. Pick a scenario in Inputs!C5 (1 = Base, 2 = Bear, 3 = Management). Everything else recalculates.
A9: Output: DCF sheet shows enterprise value, the bridge to equity and an implied value per share next to the market price. Sensitivity sheet shows how that moves with the discount rate, long term growth and the exit multiple.
A11: What this is not: a recommendation to buy or sell anything. It is a model with stated assumptions. The first combined quarter has not been reported, so the pro forma base is an estimate built from two separate companies' filings.
A13: Biggest judgments, in order of how much they move the answer: (1) how much of the $6 billion synergy target is realized and when, (2) how fast linear television revenue declines, (3) the discount rate on a company with about $84 billion of net debt, (4) cash content spend, which sits inside working capital here.
A15: Sheets: Inputs, Historical, Forecast, WACC, DCF, Sensitivity, Sources.

Sheet Inputs
A1: Inputs and scenarios
A2: Skydance Corporation (NYSE: SKYD), pro forma for Warner Bros. Discovery. USD millions unless labelled. Blue = input, black = formula, green = link to another sheet.
A4: Scenario selector
A5: Active scenario (1 Base, 2 Bear, 3 Management) | C5: 1
A6: Active scenario name | C6: =CHOOSE(C5,"Base","Bear","Management") -> Base
A8: Pro forma 2025 base (USD m) | B8: Paramount | C8: WBD | D8: Combined | I8: Source
A9: Revenue 2025 | B9: 28891 | C9: 37300 | D9: =B9+C9 -> 66191 | I9: Paramount FY2025 combined Predecessor plus Successor [3]; WBD FY2025 [17]
A10: Adjusted EBITDA 2025 (before stock comp) | B10: 3349 | C10: 8700 | D10: =B10+C10 -> 12049 | I10: Paramount adjusted OIBDA 3,076 plus SBC 273 [3]; WBD adjusted EBITDA [17]
A11: Stock based compensation 2025 | B11: 273 | C11: 600 | D11: =B11+C11 -> 873 | I11: Paramount [3]; WBD estimate, not disclosed in sources read, flagged
A12: Capital expenditures 2025 | B12: 296 | C12: 1100 | D12: =B12+C12 -> 1396 | I12: Paramount [3]; WBD run rate of about 275 a quarter [18]
A13: Depreciation and amortization for tax (run rate) | B13: 1450 | C13: 3000 | D13: =B13+C13 -> 4450 | I13: Paramount Successor run rate [3][4][5]; WBD analyst estimate of deductible D and A, flagged
A16: Revenue build, 2026E base (USD m) | B16: Paramount | C16: WBD | D16: Combined | I16: Source
A17: Streaming | B17: 9500 | C17: 11800 | D17: =B17+C17 -> 21300 | I17: Paramount DTC run rate from Q4 2025 to Q2 2026 [3][4][5]; WBD streaming Q2 2026 annualized [18]
A18: Linear television networks | B18: 14000 | C18: 16000 | D18: =B18+C18 -> 30000 | I18: Paramount TV Media run rate [3][4][5]; WBD Global Linear Networks Q2 2026 annualized [18]
A19: Studios and licensing | B19: 6500 | C19: 9000 | D19: =B19+C19 -> 15500 | I19: Paramount Studios run rate [4][5]; WBD Studios Q2 2026 annualized, a weak quarter, flagged [18]
A20: Total 2026E revenue | D20: =SUM(D17:D19) -> 66800 | I20: Check: Street consensus 2026 revenue is about 66,700 on a pro forma basis [14]
A22: Drivers by scenario | B22: 2026E | C22: 2027E | D22: 2028E | E22: 2029E | F22: 2030E | G22: 2031E | J22: Note
A23: Streaming revenue growth: Base | B23: 0.09 | C23: 0.08 | D23: 0.07 | E23: 0.06 | F23: 0.05 | G23: 0.04 | I23: Paramount DTC grew 9 to 11 percent and WBD streaming 10 percent in Q2 2026 [5][18]. Base fades toward market growth.
A24: Streaming revenue growth: Bear | B24: 0.06 | C24: 0.04 | D24: 0.03 | E24: 0.02 | F24: 0.02 | G24: 0.02
A25: Streaming revenue growth: Management | B25: 0.1 | C25: 0.1 | D25: 0.09 | E25: 0.08 | F25: 0.07 | G25: 0.06
A26: Streaming revenue growth: ACTIVE | B26: =CHOOSE($C$5,B23,B24,B25) -> 0.09 | C26: =CHOOSE($C$5,C23,C24,C25) -> 0.08 | D26: =CHOOSE($C$5,D23,D24,D25) -> 0.07 | E26: =CHOOSE($C$5,E23,E24,E25) -> 0.06 | F26: =CHOOSE($C$5,F23,F24,F25) -> 0.05 | G26: =CHOOSE($C$5,G23,G24,G25) -> 0.04
A28: Linear networks revenue growth: Base | B28: -0.08 | C28: -0.08 | D28: -0.07 | E28: -0.07 | F28: -0.06 | G28: -0.06 | I28: Paramount TV Media fell 6 to 9 percent and WBD linear 17 percent in Q2 2026, the latter partly NBA rights [5][18].
A29: Linear networks revenue growth: Bear | B29: -0.11 | C29: -0.11 | D29: -0.1 | E29: -0.1 | F29: -0.09 | G29: -0.09
A30: Linear networks revenue growth: Management | B30: -0.06 | C30: -0.06 | D30: -0.05 | E30: -0.05 | F30: -0.05 | G30: -0.05
A31: Linear networks revenue growth: ACTIVE | B31: =CHOOSE($C$5,B28,B29,B30) -> -0.08 | C31: =CHOOSE($C$5,C28,C29,C30) -> -0.08 | D31: =CHOOSE($C$5,D28,D29,D30) -> -0.07 | E31: =CHOOSE($C$5,E28,E29,E30) -> -0.07 | F31: =CHOOSE($C$5,F28,F29,F30) -> -0.06 | G31: =CHOOSE($C$5,G28,G29,G30) -> -0.06
A33: Studios revenue growth: Base | B33: 0.03 | C33: 0.03 | D33: 0.03 | E33: 0.03 | F33: 0.03 | G33: 0.03 | I33: Slate driven and lumpy. Held near inflation.
A34: Studios revenue growth: Bear | B34: 0 | C34: 0 | D34: 0.01 | E34: 0.01 | F34: 0.01 | G34: 0.01
A35: Studios revenue growth: Management | B35: 0.05 | C35: 0.05 | D35: 0.04 | E35: 0.04 | F35: 0.04 | G35: 0.04
A36: Studios revenue growth: ACTIVE | B36: =CHOOSE($C$5,B33,B34,B35) -> 0.03 | C36: =CHOOSE($C$5,C33,C34,C35) -> 0.03 | D36: =CHOOSE($C$5,D33,D34,D35) -> 0.03 | E36: =CHOOSE($C$5,E33,E34,E35) -> 0.03 | F36: =CHOOSE($C$5,F33,F34,F35) -> 0.03 | G36: =CHOOSE($C$5,G33,G34,G35) -> 0.03
A38: Underlying EBITDA margin before synergies: Base | B38: 0.184 | C38: 0.178 | D38: 0.172 | E38: 0.167 | F38: 0.163 | G38: 0.16 | I38: 2026E anchored to Paramount guidance of 3,850 plus WBD trailing 8,800 on 66,500 of revenue [5][18]. Drifts down as linear shrinks.
A39: Underlying EBITDA margin before synergies: Bear | B39: 0.18 | C39: 0.168 | D39: 0.158 | E39: 0.15 | F39: 0.143 | G39: 0.138
A40: Underlying EBITDA margin before synergies: Management | B40: 0.186 | C40: 0.184 | D40: 0.182 | E40: 0.18 | F40: 0.178 | G40: 0.176
A41: Underlying EBITDA margin before synergies: ACTIVE | B41: =CHOOSE($C$5,B38,B39,B40) -> 0.184 | C41: =CHOOSE($C$5,C38,C39,C40) -> 0.178 | D41: =CHOOSE($C$5,D38,D39,D40) -> 0.172 | E41: =CHOOSE($C$5,E38,E39,E40) -> 0.167 | F41: =CHOOSE($C$5,F38,F39,F40) -> 0.163 | G41: =CHOOSE($C$5,G38,G39,G40) -> 0.16
A43: Realized synergies, cumulative run rate: Base | B43: 0 | C43: 1750 | D43: 3750 | E43: 5100 | F43: 5400 | G43: 5500 | I43: Management targets at least 6,000 within three years [12]. Base follows the Debtwire path [10]. Bear takes half.
A44: Realized synergies, cumulative run rate: Bear | B44: 0 | C44: 1000 | D44: 2000 | E44: 2750 | F44: 3000 | G44: 3000
A45: Realized synergies, cumulative run rate: Management | B45: 0 | C45: 2000 | D45: 4500 | E45: 6000 | F45: 6000 | G45: 6000
A46: Realized synergies, cumulative run rate: ACTIVE | B46: =CHOOSE($C$5,B43,B44,B45) -> 0 | C46: =CHOOSE($C$5,C43,C44,C45) -> 1750 | D46: =CHOOSE($C$5,D43,D44,D45) -> 3750 | E46: =CHOOSE($C$5,E43,E44,E45) -> 5100 | F46: =CHOOSE($C$5,F43,F44,F45) -> 5400 | G46: =CHOOSE($C$5,G43,G44,G45) -> 5500
A48: Cash cost to achieve synergies and integration: Base | B48: 1500 | C48: 2500 | D48: 2000 | E48: 800 | F48: 300 | G48: 0 | I48: 2026 is Paramount's 800 of transformation cost plus WBD transaction costs [5][18]. Roughly one times run rate in total.
A49: Cash cost to achieve synergies and integration: Bear | B49: 1500 | C49: 2500 | D49: 2000 | E49: 1000 | F49: 500 | G49: 0
A50: Cash cost to achieve synergies and integration: Management | B50: 1500 | C50: 2000 | D50: 1500 | E50: 500 | F50: 0 | G50: 0
...

Sheet Historical
A1: Historical results, the two companies separately
A2: Skydance Corporation (NYSE: SKYD), pro forma for Warner Bros. Discovery. USD millions unless labelled. Blue = input, black = formula, green = link to another sheet.
A4: Paramount Global then Paramount Skydance (USD m) | B4: FY2022 | C4: FY2023 | D4: FY2024 | E4: FY2025 | F4: H1 2026 | G4: Source
A5: Revenue | B5: 30154 | C5: 29652 | D5: 29213 | E5: 28891 | F5: 14260 | G5: [9][3][5]
A6: Adjusted OIBDA (after stock comp) | B6: 3276 | C6: 2390 | D6: 3118 | E6: 3076 | G6: [9][3]
A7: Adjusted EBITDA (before stock comp, new metric 2026) | F7: 2260 | G7: [5]
A8: Operating income (loss) | B8: 2342 | C8: -451 | D8: -5269 | E8: 934 | F8: 1091 | G8: [9][3][5]
A9: Depreciation and amortization | B9: 378 | C9: 418 | D9: 392 | E9: 794 | F9: 726 | G9: [9][3][5]
A10: Stock based compensation | B10: 172 | C10: 177 | D10: 245 | E10: 273 | F10: 152 | G10: [9][3][5]
A11: Restructuring, transaction and other items | B11: 585 | C11: -31 | D11: 747 | E11: 1185 | F11: 291 | G11: [9][3][5]
A12: Operating cash flow | B12: -142 | C12: 384 | D12: 752 | E12: 649 | F12: 504 | G12: [9][3][5]
A13: Capital expenditures | B13: 358 | C13: 328 | D13: 263 | E13: 296 | F13: 150 | G13: [9][3][5]
A14: Free cash flow | B14: -500 | C14: 56 | D14: 489 | E14: 353 | F14: 354 | G14: [9][3][5]
A15: Paramount+ subscribers, millions, year end | C15: 67.5 | E15: 78.9 | F15: 81.6 | G15: [9][3][5]
A16: Adjusted OIBDA margin | B16: =IF(B5=0,0,B6/B5) -> 0.1086423 | C16: =IF(C5=0,0,C6/C5) -> 0.080601646 | D16: =IF(D5=0,0,D6/D5) -> 0.1067333 | E16: =IF(E5=0,0,E6/E5) -> 0.10646914
A17: Free cash flow as percent of revenue | B17: =IF(B5=0,0,B14/B5) -> -0.016581548 | C17: =IF(C5=0,0,C14/C5) -> 0.0018885741 | D17: =IF(D5=0,0,D14/D5) -> 0.016739123 | E17: =IF(E5=0,0,E14/E5) -> 0.012218338 | F17: =IF(F5=0,0,F14/F5) -> 0.024824684
A20: Warner Bros. Discovery (USD m) | E20: FY2025 | F20: Q2 2026 | G20: Source
A21: Revenue | E21: 37300 | F21: 8717 | G21: [17][18]
A22: Adjusted EBITDA | E22: 8700 | F22: 1879 | G22: [17][18]
A23: Streaming revenue | F23: 3079 | G23: [18]
A24: Studios revenue | F24: 2328 | G24: [18]
A25: Global Linear Networks revenue | F25: 3991 | G25: [18]
A26: Streaming adjusted EBITDA | F26: 512 | G26: [18]
A27: Studios adjusted EBITDA | F27: 96 | G27: [18]
A28: Global Linear Networks adjusted EBITDA | F28: 1446 | G28: [18]
A29: Operating cash flow | E29: 4300 | F29: 848 | G29: [17][18]
A30: Capital expenditures | F30: 276 | G30: [18]
A31: Free cash flow | E31: 3100 | F31: 572 | G31: [17][18]
A32: Net debt, period end | E32: 29000 | F32: 29700 | G32: [17][18]
A33: Net leverage | E33: 3.3 | F33: 3.4 | G33: [17][18]
A35: Pro forma combined 2025 per the company's July 2026 8-K: revenue 66,133, net loss to parent (5,758), with purchase accounting and transaction costs [6].

Sheet Forecast
A1: Forecast, pro forma combined
A2: Skydance Corporation (NYSE: SKYD), pro forma for Warner Bros. Discovery. USD millions unless labelled. Blue = input, black = formula, green = link to another sheet.
A4: USD millions | B4: 2026E | C4: 2027E | D4: 2028E | E4: 2029E | F4: 2030E | G4: 2031E | H4: Note
A5: Streaming revenue | B5: =Inputs!D17 -> 21300 | C5: =B5*(1+Inputs!C$26) -> 23004 | D5: =C5*(1+Inputs!D$26) -> 24614.28 | E5: =D5*(1+Inputs!E$26) -> 26091.137 | F5: =E5*(1+Inputs!F$26) -> 27395.694 | G5: =F5*(1+Inputs!G$26) -> 28491.521 | H5: 2026E segment base is the run rate build on Inputs rows 17 to 19.
A6: Linear networks revenue | B6: =Inputs!D18 -> 30000 | C6: =B6*(1+Inputs!C$31) -> 27600 | D6: =C6*(1+Inputs!D$31) -> 25668 | E6: =D6*(1+Inputs!E$31) -> 23871.24 | F6: =E6*(1+Inputs!F$31) -> 22438.966 | G6: =F6*(1+Inputs!G$31) -> 21092.628
A7: Studios and licensing revenue | B7: =Inputs!D19 -> 15500 | C7: =B7*(1+Inputs!C$36) -> 15965 | D7: =C7*(1+Inputs!D$36) -> 16443.95 | E7: =D7*(1+Inputs!E$36) -> 16937.268 | F7: =E7*(1+Inputs!F$36) -> 17445.387 | G7: =F7*(1+Inputs!G$36) -> 17968.748
A8: Total revenue | B8: =SUM(B5:B7) -> 66800 | C8: =SUM(C5:C7) -> 66569 | D8: =SUM(D5:D7) -> 66726.23 | E8: =SUM(E5:E7) -> 66899.645 | F8: =SUM(F5:F7) -> 67280.046 | G8: =SUM(G5:G7) -> 67552.897
A9: Revenue growth | C9: =C8/B8-1 -> -0.0034580838 | D9: =D8/C8-1 -> 0.0023619102 | E9: =E8/D8-1 -> 0.0025989075 | F9: =F8/E8-1 -> 0.0056861362 | G9: =G8/F8-1 -> 0.0040554581
A11: Underlying EBITDA before synergies | B11: =B8*Inputs!B$41 -> 12291.2 | C11: =C8*Inputs!C$41 -> 11849.282 | D11: =D8*Inputs!D$41 -> 11476.912 | E11: =E8*Inputs!E$41 -> 11172.241 | F11: =F8*Inputs!F$41 -> 10966.647 | G11: =G8*Inputs!G$41 -> 10808.464
A12: Realized synergies | B12: =Inputs!B$46 -> 0 | C12: =Inputs!C$46 -> 1750 | D12: =Inputs!D$46 -> 3750 | E12: =Inputs!E$46 -> 5100 | F12: =Inputs!F$46 -> 5400 | G12: =Inputs!G$46 -> 5500
A13: Adjusted EBITDA | B13: =B11+B12 -> 12291.2 | C13: =C11+C12 -> 13599.282 | D13: =D11+D12 -> 15226.912 | E13: =E11+E12 -> 16272.241 | F13: =F11+F12 -> 16366.647 | G13: =G11+G12 -> 16308.464
A14: Adjusted EBITDA margin | B14: =B13/B8 -> 0.184 | C14: =C13/C8 -> 0.20428851 | D14: =D13/D8 -> 0.22819979 | E14: =E13/E8 -> 0.24323359 | F14: =F13/F8 -> 0.24326154 | G14: =G13/G8 -> 0.24141768
A15: Less stock based compensation | B15: =-Inputs!B$56 -> -900 | C15: =-Inputs!C$56 -> -900 | D15: =-Inputs!D$56 -> -900 | E15: =-Inputs!E$56 -> -900 | F15: =-Inputs!F$56 -> -900 | G15: =-Inputs!G$56 -> -900
A16: Less cash cost of synergies and integration | B16: =-Inputs!B$51 -> -1500 | C16: =-Inputs!C$51 -> -2500 | D16: =-Inputs!D$51 -> -2000 | E16: =-Inputs!E$51 -> -800 | F16: =-Inputs!F$51 -> -300 | G16: =-Inputs!G$51 -> 0
A17: EBITDA after stock comp and integration cash | B17: =B13+B15+B16 -> 9891.2 | C17: =C13+C15+C16 -> 10199.282 | D17: =D13+D15+D16 -> 12326.912 | E17: =E13+E15+E16 -> 14572.241 | F17: =F13+F15+F16 -> 15166.647 | G17: =G13+G15+G16 -> 15408.464
A18: Less tax depreciation and amortization | B18: =-Inputs!B$71 -> -4450 | C18: =-Inputs!C$71 -> -4400 | D18: =-Inputs!D$71 -> -4300 | E18: =-Inputs!E$71 -> -4200 | F18: =-Inputs!F$71 -> -4100 | G18: =-Inputs!G$71 -> -4000
A19: Taxable operating profit | B19: =B17+B18 -> 5441.2 | C19: =C17+C18 -> 5799.282 | D19: =D17+D18 -> 8026.9116 | E19: =E17+E18 -> 10372.241 | F19: =F17+F18 -> 11066.647 | G19: =G17+G18 -> 11408.464
A20: Cash taxes | B20: =-MAX(0,B19)*Inputs!$B$85 -> -1251.476 | C20: =-MAX(0,C19)*Inputs!$B$85 -> -1333.8349 | D20: =-MAX(0,D19)*Inputs!$B$85 -> -1846.1897 | E20: =-MAX(0,E19)*Inputs!$B$85 -> -2385.6154 | F20: =-MAX(0,F19)*Inputs!$B$85 -> -2545.3289 | G20: =-MAX(0,G19)*Inputs!$B$85 -> -2623.9466
A21: Less capital expenditures | B21: =-B8*Inputs!B$61 -> -1402.8 | C21: =-C8*Inputs!C$61 -> -1397.949 | D21: =-D8*Inputs!D$61 -> -1401.2508 | E21: =-E8*Inputs!E$61 -> -1404.8926 | F21: =-F8*Inputs!F$61 -> -1412.881 | G21: =-G8*Inputs!G$61 -> -1418.6108
A22: Less working capital and content investment | B22: =-B8*Inputs!B$66 -> -801.6 | C22: =-C8*Inputs!C$66 -> -665.69 | D22: =-D8*Inputs!D$66 -> -600.53607 | E22: =-E8*Inputs!E$66 -> -535.19716 | F22: =-F8*Inputs!F$66 -> -470.96032 | G22: =-G8*Inputs!G$66 -> -405.31738
A23: Unlevered free cash flow | B23: =B17+B20+B21+B22 -> 6435.324 | C23: =C17+C20+C21+C22 -> 6801.8081 | D23: =D17+D20+D21+D22 -> 8478.935 | E23: =E17+E20+E21+E22 -> 10246.536 | F23: =F17+F20+F21+F22 -> 10737.477 | G23: =G17+G20+G21+G22 -> 10960.589
A24: Conversion, unlevered FCF over adjusted EBITDA | B24: =B23/B13 -> 0.52357166 | C24: =C23/C13 -> 0.50015936 | D24: =D23/D13 -> 0.55683879 | E24: =E23/E13 -> 0.6296942 | F24: =F23/F13 -> 0.65605844 | G24: =G23/G13 -> 0.67207979
A26: Memo: EBITDA on Debtwire basis, 2027E 13,700 with synergies, 2030E base 17,200 [10]; management targets FCF above 10,000 by 2030 [12], which is after interest.

Sheet WACC
A1: Cost of capital
A2: Skydance Corporation (NYSE: SKYD), pro forma for Warner Bros. Discovery. USD millions unless labelled. Blue = input, black = formula, green = link to another sheet.
A4: Input or step | B4: Value | C4: Basis
A5: Risk free rate, 10 year Treasury, October 22, 2026 | B5: 0.0495 | C5: [16]
A6: Equity risk premium | B6: 0.045 | C6: Analyst input. Kroll's recommended US premium was 5.0 percent in late 2025; 4.5 percent reflects a higher risk free rate.
A7: Unlevered beta, diversified media | B7: 0.9 | C7: Analyst input. The quoted 1.55 levered beta [15] is on legacy Paramount history and a different capital structure, so it is relevered here instead.
A8: Market value of equity | B8: =Inputs!$B$74*Inputs!$B$75 -> 39160.8 | C8: Price times shares
A9: Net debt | B9: =Inputs!$B$78-Inputs!$B$79 -> 84300 | C9: [10]
A10: Debt to equity | B10: =B9/B8 -> 2.1526629
A11: Tax rate | B11: =Inputs!$B$85 -> 0.23
A12: Levered beta | B12: =B7*(1+(1-B11)*B10) -> 2.3917954 | C12: Hamada relevering
A13: Cost of equity | B13: =B5+B12*B6 -> 0.15713079 | C13: CAPM
A14: Pre tax cost of debt | B14: 0.08 | C14: New first lien 7.05 percent and second lien 8.875 percent coupons, legacy unsecured yielding 10 to 13 percent [10]. Blended judgment.
A15: After tax cost of debt | B15: =B14*(1-B11) -> 0.0616
A16: Weight of equity | B16: =B8/(B8+B9) -> 0.31719218 | C16: Market weights at the October 23 close
A17: Weight of debt | B17: =B9/(B8+B9) -> 0.68280782
A18: WACC | B18: =B16*B13+B17*B15 -> 0.09190162
A20: Why market weights: management targets 3.0x net leverage by 2029 [12], which would raise the equity weight and the WACC over time. Using today's 68 percent debt weight gives a lower WACC than a target structure would. The Sensitivity sheet covers 8 to 11 percent.

Sheet DCF
A1: Discounted cash flow
A2: Skydance Corporation (NYSE: SKYD), pro forma for Warner Bros. Discovery. USD millions unless labelled. Blue = input, black = formula, green = link to another sheet.
A4: USD millions | B4: 2026E | C4: 2027E | D4: 2028E | E4: 2029E | F4: 2030E | G4: 2031E | H4: Note
A5: Unlevered free cash flow | B5: =Forecast!B23 -> 6435.324 | C5: =Forecast!C23 -> 6801.8081 | D5: =Forecast!D23 -> 8478.935 | E5: =Forecast!E23 -> 10246.536 | F5: =Forecast!F23 -> 10737.477 | G5: =Forecast!G23 -> 10960.589
A6: Fraction of year included | B6: =Inputs!$B$82 -> 0.19 | C6: 1 | D6: 1 | E6: 1 | F6: 1 | G6: 1 | H6: Only the rest of 2026 is counted from the October 24 valuation date.
A7: Cash flow included | B7: =B5*B6 -> 1222.7116 | C7: =C5*C6 -> 6801.8081 | D7: =D5*D6 -> 8478.935 | E7: =E5*E6 -> 10246.536 | F7: =F5*F6 -> 10737.477 | G7: =G5*G6 -> 10960.589
A8: Discount period, years from valuation date, mid year | B8: =B6/2 -> 0.095 | C8: =B6+1-0.5 -> 0.69 | D8: =B6+2-0.5 -> 1.69 | E8: =B6+3-0.5 -> 2.69 | F8: =B6+4-0.5 -> 3.69 | G8: =B6+5-0.5 -> 4.69
A9: Discount factor | B9: =1/(1+WACC!$B$18)^B8 -> 0.99168231 | C9: =1/(1+WACC!$B$18)^C8 -> 0.94113815 | D9: =1/(1+WACC!$B$18)^D8 -> 0.86192577 | E9: =1/(1+WACC!$B$18)^E8 -> 0.78938043 | F9: =1/(1+WACC!$B$18)^F8 -> 0.72294099 | G9: =1/(1+WACC!$B$18)^G8 -> 0.66209352
A10: Present value | B10: =B7*B9 -> 1212.5414 | C10: =C7*C9 -> 6401.4411 | D10: =D7*D9 -> 7308.2126 | E10: =E7*E9 -> 8088.4148 | F10: =F7*F9 -> 7762.5624 | G10: =G7*G9 -> 7256.9348
A12: Terminal value, perpetuity growth method
A13: Long term growth | B13: =Inputs!$B$83 -> 0.015
A14: Terminal year cash flow, 2031E grown one year | B14: =G5*(1+B13) -> 11124.998
A15: Terminal value at end of 2031 | B15: =B14/(WACC!B18-B13) -> 144665.32
A16: Discount factor, end of 2031 | B16: =1/(1+WACC!B18)^(B6+5) -> 0.63361811
A17: Present value of terminal value | B17: =B15*B16 -> 91662.568
A18: Implied exit multiple of 2031E EBITDA | B18: =B15/Forecast!G13 -> 8.8705672
A20: Terminal value, exit multiple method
A21: Exit multiple | B21: =Inputs!$B$84 -> 7
A22: Terminal value at end of 2031 | B22: =B21*Forecast!G13 -> 114159.24
A23: Present value of terminal value | B23: =B22*B16 -> 72333.365
A24: Implied perpetuity growth | B24: =(B22*WACC!B18-G5)/(B22+G5) -> -0.0037497588
A26: Enterprise value and bridge to equity | B26: Perpetuity | C26: Exit multiple | H26: Note
A27: Sum of present value of forecast cash flows | B27: =SUM(B10:G10) -> 38030.107 | C27: =B27 -> 38030.107
A28: Present value of terminal value | B28: =B17 -> 91662.568 | C28: =B23 -> 72333.365
A29: Enterprise value | B29: =B27+B28 -> 129692.67 | C29: =C27+C28 -> 110363.47
A30: Terminal value share of enterprise value | B30: =B28/B29 -> 0.7067675 | C30: =C28/C29 -> 0.65541038
A31: Less net debt | B31: =-WACC!B9 -> -84300 | C31: =B31 -> -84300
A32: Less noncontrolling interests | B32: =-Inputs!$B$80 -> -1039 | C32: =B32 -> -1039
A33: Equity value | B33: =B29+B31+B32 -> 44353.675 | C33: =C29+C31+C32 -> 25024.472
A34: Shares outstanding, millions | B34: =Inputs!$B$75 -> 5040 | C34: =B34 -> 5040
A35: Implied value per share before warrants | B35: =B33/B34 -> 8.8003323 | C35: =C33/C34 -> 4.965173
A36: Warrant dilution, treasury stock method, millions of shares | B36: =IF(B35>Inputs!$B$77,Inputs!$B$76*(1-Inputs!$B$77/B35),0) -> 0 | C36: =IF(C35>Inputs!$B$77,Inputs!$B$76*(1-Inputs!$B$77/C35),0) -> 0
A37: Implied value per share after warrants | B37: =B33/(B34+B36) -> 8.8003323 | C37: =C33/(C34+C36) -> 4.965173 | H37: This is a model output under stated assumptions, not a recommendation.
A38: Market price, October 23, 2026 | B38: =Inputs!$B$74 -> 7.77 | C38: =B38 -> 7.77
A39: Model value over market price | B39: =B37/B38-1 -> 0.1326039 | C39: =C37/C38-1 -> -0.36098159
A40: Market enterprise value for reference | B40: =WACC!B8+WACC!B9+Inputs!$B$80 -> 124499.8
A41: Market EV to 2026E adjusted EBITDA | B41: =B40/Forecast!B13 -> 10.129182
A42: Model EV to 2026E adjusted EBITDA | B42: =B29/Forecast!B13 -> 10.551669 | C42: =C29/Forecast!B13 -> 8.9790641

Sheet Sensitivity
A1: Sensitivity of implied value per share
A2: Skydance Corporation (NYSE: SKYD), pro forma for Warner Bros. Discovery. USD millions unless labelled. Blue = input, black = formula, green = link to another sheet.
A4: Perpetuity growth method: WACC down, long term growth across. Value per share after warrants, $.
A5: WACC \ growth | B5: 0.005 | C5: 0.01 | D5: 0.015 | E5: 0.02 | F5: 0.025
A6: 0.08 | B6: =((SUMPRODUCT(DCF!$B$7:$G$7/(1+$A6)^DCF!$B$8:$G$8)+DCF!$G$5*(1+B$5)/($A6-B$5)/(1+$A6)^(DCF!$B$6+5))+DCF!$B$31+DCF!$B$32)/(DCF!$B$34+IF((((SUMPRODUCT(DCF!$B$7:$G$7/(1+$A6)^DCF!$B$8:$G$8)+DCF!$G$5*(1+B$5)/($A6-B$5)/(1+$A6)^(DCF!$B$6+5))+DCF!$B$31+DCF!$B$32)/DCF!$B$34)>Inputs!$B$77,Inputs!$B$76*(1-Inputs!$B$77/(((SUMPRODUCT(DCF!$B$7:$G$7/(1+$A6)^DCF!$B$8:$G$8)+DCF!$G$5*(1+B$5)/($A6-B$5)/(1+$A6)^(DCF!$B$6+5))+DCF!$B$31+DCF!$B$32)/DCF!$B$34)),0)) -> 10.382986 | C6: =((SUMPRODUCT(DCF!$B$7:$G$7/(1+$A6)^DCF!$B$8:$G$8)+DCF!$G$5*(1+C$5)/($A6-C$5)/(1+$A6)^(DCF!$B$6+5))+DCF!$B$31+DCF!$B$32)/(DCF!$B$34+IF((((SUMPRODUCT(DCF!$B$7:$G$7/(1+$A6)^DCF!$B$8:$G$8)+DCF!$G$5*(1+C$5)/($A6-C$5)/(1+$A6)^(DCF!$B$6+5))+DCF!$B$31+DCF!$B$32)/DCF!$B$34)>Inputs!$B$77,Inputs!$B$76*(1-Inputs!$B$77/(((SUMPRODUCT(DCF!$B$7:$G$7/(1+$A6)^DCF!$B$8:$G$8)+DCF!$G$5*(1+C$5)/($A6-C$5)/(1+$A6)^(DCF!$B$6+5))+DCF!$B$31+DCF!$B$32)/DCF!$B$34)),0)) -> 11.883253 | D6: =((SUMPRODUCT(DCF!$B$7:$G$7/(1+$A6)^DCF!$B$8:$G$8)+DCF!$G$5*(1+D$5)/($A6-D$5)/(1+$A6)^(DCF!$B$6+5))+DCF!$B$31+DCF!$B$32)/(DCF!$B$34+IF((((SUMPRODUCT(DCF!$B$7:$G$7/(1+$A6)^DCF!$B$8:$G$8)+DCF!$G$5*(1+D$5)/($A6-D$5)/(1+$A6)^(DCF!$B$6+5))+DCF!$B$31+DCF!$B$32)/DCF!$B$34)>Inputs!$B$77,Inputs!$B$76*(1-Inputs!$B$77/(((SUMPRODUCT(DCF!$B$7:$G$7/(1+$A6)^DCF!$B$8:$G$8)+DCF!$G$5*(1+D$5)/($A6-D$5)/(1+$A6)^(DCF!$B$6+5))+DCF!$B$31+DCF!$B$32)/DCF!$B$34)),0)) -> 13.465199 | E6: =((SUMPRODUCT(DCF!$B$7:$G$7/(1+$A6)^DCF!$B$8:$G$8)+DCF!$G$5*(1+E$5)/($A6-E$5)/(1+$A6)^(DCF!$B$6+5))+DCF!$B$31+DCF!$B$32)/(DCF!$B$34+IF((((SUMPRODUCT(DCF!$B$7:$G$7/(1+$A6)^DCF!$B$8:$G$8)+DCF!$G$5*(1+E$5)/($A6-E$5)/(1+$A6)^(DCF!$B$6+5))+DCF!$B$31+DCF!$B$32)/DCF!$B$34)>Inputs!$B$77,Inputs!$B$76*(1-Inputs!$B$77/(((SUMPRODUCT(DCF!$B$7:$G$7/(1+$A6)^DCF!$B$8:$G$8)+DCF!$G$5*(1+E$5)/($A6-E$5)/(1+$A6)^(DCF!$B$6+5))+DCF!$B$31+DCF!$B$32)/DCF!$B$34)),0)) -> 15.301714 | F6: =((SUMPRODUCT(DCF!$B$7:$G$7/(1+$A6)^DCF!$B$8:$G$8)+DCF!$G$5*(1+F$5)/($A6-F$5)/(1+$A6)^(DCF!$B$6+5))+DCF!$B$31+DCF!$B$32)/(DCF!$B$34+IF((((SUMPRODUCT(DCF!$B$7:$G$7/(1+$A6)^DCF!$B$8:$G$8)+DCF!$G$5*(1+F$5)/($A6-F$5)/(1+$A6)^(DCF!$B$6+5))+DCF!$B$31+DCF!$B$32)/DCF!$B$34)>Inputs!$B$77,Inputs!$B$76*(1-Inputs!$B$77/(((SUMPRODUCT(DCF!$B$7:$G$7/(1+$A6)^DCF!$B$8:$G$8)+DCF!$G$5*(1+F$5)/($A6-F$5)/(1+$A6)^(DCF!$B$6+5))+DCF!$B$31+DCF!$B$32)/DCF!$B$34)),0)) -> 17.475375
A7: 0.085 | B7: =((SUMPRODUCT(DCF!$B$7:$G$7/(1+$A7)^DCF!$B$8:$G$8)+DCF!$G$5*(1+B$5)/($A7-B$5)/(1+$A7)^(DCF!$B$6+5))+DCF!$B$31+DCF!$B$32)/(DCF!$B$34+IF((((SUMPRODUCT(DCF!$B$7:$G$7/(1+$A7)^DCF!$B$8:$G$8)+DCF!$G$5*(1+B$5)/($A7-B$5)/(1+$A7)^(DCF!$B$6+5))+DCF!$B$31+DCF!$B$32)/DCF!$B$34)>Inputs!$B$77,Inputs!$B$76*(1-Inputs!$B$77/(((SUMPRODUCT(DCF!$B$7:$G$7/(1+$A7)^DCF!$B$8:$G$8)+DCF!$G$5*(1+B$5)/($A7-B$5)/(1+$A7)^(DCF!$B$6+5))+DCF!$B$31+DCF!$B$32)/DCF!$B$34)),0)) -> 8.6317193 | C7: =((SUMPRODUCT(DCF!$B$7:$G$7/(1+$A7)^DCF!$B$8:$G$8)+DCF!$G$5*(1+C$5)/($A7-C$5)/(1+$A7)^(DCF!$B$6+5))+DCF!$B$31+DCF!$B$32)/(DCF!$B$34+IF((((SUMPRODUCT(DCF!$B$7:$G$7/(1+$A7)^DCF!$B$8:$G$8)+DCF!$G$5*(1+C$5)/($A7-C$5)/(1+$A7)^(DCF!$B$6+5))+DCF!$B$31+DCF!$B$32)/DCF!$B$34)>Inputs!$B$77,Inputs!$B$76*(1-Inputs!$B$77/(((SUMPRODUCT(DCF!$B$7:$G$7/(1+$A7)^DCF!$B$8:$G$8)+DCF!$G$5*(1+C$5)/($A7-C$5)/(1+$A7)^(DCF!$B$6+5))+DCF!$B$31+DCF!$B$32)/DCF!$B$34)),0)) -> 9.9192912 | D7: =((SUMPRODUCT(DCF!$B$7:$G$7/(1+$A7)^DCF!$B$8:$G$8)+DCF!$G$5*(1+D$5)/($A7-D$5)/(1+$A7)^(DCF!$B$6+5))+DCF!$B$31+DCF!$B$32)/(DCF!$B$34+IF((((SUMPRODUCT(DCF!$B$7:$G$7/(1+$A7)^DCF!$B$8:$G$8)+DCF!$G$5*(1+D$5)/($A7-D$5)/(1+$A7)^(DCF!$B$6+5))+DCF!$B$31+DCF!$B$32)/DCF!$B$34)>Inputs!$B$77,Inputs!$B$76*(1-Inputs!$B$77/(((SUMPRODUCT(DCF!$B$7:$G$7/(1+$A7)^DCF!$B$8:$G$8)+DCF!$G$5*(1+D$5)/($A7-D$5)/(1+$A7)^(DCF!$B$6+5))+DCF!$B$31+DCF!$B$32)/DCF!$B$34)),0)) -> 11.390802 | E7: =((SUMPRODUCT(DCF!$B$7:$G$7/(1+$A7)^DCF!$B$8:$G$8)+DCF!$G$5*(1+E$5)/($A7-E$5)/(1+$A7)^(DCF!$B$6+5))+DCF!$B$31+DCF!$B$32)/(DCF!$B$34+IF((((SUMPRODUCT(DCF!$B$7:$G$7/(1+$A7)^DCF!$B$8:$G$8)+DCF!$G$5*(1+E$5)/($A7-E$5)/(1+$A7)^(DCF!$B$6+5))+DCF!$B$31+DCF!$B$32)/DCF!$B$34)>Inputs!$B$77,Inputs!$B$76*(1-Inputs!$B$77/(((SUMPRODUCT(DCF!$B$7:$G$7/(1+$A7)^DCF!$B$8:$G$8)+DCF!$G$5*(1+E$5)/($A7-E$5)/(1+$A7)^(DCF!$B$6+5))+DCF!$B$31+DCF!$B$32)/DCF!$B$34)),0)) -> 12.987795 | F7: =((SUMPRODUCT(DCF!$B$7:$G$7/(1+$A7)^DCF!$B$8:$G$8)+DCF!$G$5*(1+F$5)/($A7-F$5)/(1+$A7)^(DCF!$B$6+5))+DCF!$B$31+DCF!$B$32)/(DCF!$B$34+IF((((SUMPRODUCT(DCF!$B$7:$G$7/(1+$A7)^DCF!$B$8:$G$8)+DCF!$G$5*(1+F$5)/($A7-F$5)/(1+$A7)^(DCF!$B$6+5))+DCF!$B$31+DCF!$B$32)/DCF!$B$34)>Inputs!$B$77,Inputs!$B$76*(1-Inputs!$B$77/(((SUMPRODUCT(DCF!$B$7:$G$7/(1+$A7)^DCF!$B$8:$G$8)+DCF!$G$5*(1+F$5)/($A7-F$5)/(1+$A7)^(DCF!$B$6+5))+DCF!$B$31+DCF!$B$32)/DCF!$B$34)),0)) -> 14.788225
A8: 0.09 | B8: =((SUMPRODUCT(DCF!$B$7:$G$7/(1+$A8)^DCF!$B$8:$G$8)+DCF!$G$5*(1+B$5)/($A8-B$5)/(1+$A8)^(DCF!$B$6+5))+DCF!$B$31+DCF!$B$32)/(DCF!$B$34+IF((((SUMPRODUCT(DCF!$B$7:$G$7/(1+$A8)^DCF!$B$8:$G$8)+DCF!$G$5*(1+B$5)/($A8-B$5)/(1+$A8)^(DCF!$B$6+5))+DCF!$B$31+DCF!$B$32)/DCF!$B$34)>Inputs!$B$77,Inputs!$B$76*(1-Inputs!$B$77/(((SUMPRODUCT(DCF!$B$7:$G$7/(1+$A8)^DCF!$B$8:$G$8)+DCF!$G$5*(1+B$5)/($A8-B$5)/(1+$A8)^(DCF!$B$6+5))+DCF!$B$31+DCF!$B$32)/DCF!$B$34)),0)) -> 7.0886561 | C8: =((SUMPRODUCT(DCF!$B$7:$G$7/(1+$A8)^DCF!$B$8:$G$8)+DCF!$G$5*(1+C$5)/($A8-C$5)/(1+$A8)^(DCF!$B$6+5))+DCF!$B$31+DCF!$B$32)/(DCF!$B$34+IF((((SUMPRODUCT(DCF!$B$7:$G$7/(1+$A8)^DCF!$B$8:$G$8)+DCF!$G$5*(1+C$5)/($A8-C$5)/(1+$A8)^(DCF!$B$6+5))+DCF!$B$31+DCF!$B$32)/DCF!$B$34)>Inputs!$B$77,Inputs!$B$76*(1-Inputs!$B$77/(((SUMPRODUCT(DCF!$B$7:$G$7/(1+$A8)^DCF!$B$8:$G$8)+DCF!$G$5*(1+C$5)/($A8-C$5)/(1+$A8)^(DCF!$B$6+5))+DCF!$B$31+DCF!$B$32)/DCF!$B$34)),0)) -> 8.2030723 | D8: =((SUMPRODUCT(DCF!$B$7:$G$7/(1+$A8)^DCF!$B$8:$G$8)+DCF!$G$5*(1+D$5)/($A8-D$5)/(1+$A8)^(DCF!$B$6+5))+DCF!$B$31+DCF!$B$32)/(DCF!$B$34+IF((((SUMPRODUCT(DCF!$B$7:$G$7/(1+$A8)^DCF!$B$8:$G$8)+DCF!$G$5*(1+D$5)/($A8-D$5)/(1+$A8)^(DCF!$B$6+5))+DCF!$B$31+DCF!$B$32)/DCF!$B$34)>Inputs!$B$77,Inputs!$B$76*(1-Inputs!$B$77/(((SUMPRODUCT(DCF!$B$7:$G$7/(1+$A8)^DCF!$B$8:$G$8)+DCF!$G$5*(1+D$5)/($A8-D$5)/(1+$A8)^(DCF!$B$6+5))+DCF!$B$31+DCF!$B$32)/DCF!$B$34)),0)) -> 9.4660773 | E8: =((SUMPRODUCT(DCF!$B$7:$G$7/(1+$A8)^DCF!$B$8:$G$8)+DCF!$G$5*(1+E$5)/($A8-E$5)/(1+$A8)^(DCF!$B$6+5))+DCF!$B$31+DCF!$B$32)/(DCF!$B$34+IF((((SUMPRODUCT(DCF!$B$7:$G$7/(1+$A8)^DCF!$B$8:$G$8)+DCF!$G$5*(1+E$5)/($A8-E$5)/(1+$A8)^(DCF!$B$6+5))+DCF!$B$31+DCF!$B$32)/DCF!$B$34)>Inputs!$B$77,Inputs!$B$76*(1-Inputs!$B$77/(((SUMPRODUCT(DCF!$B$7:$G$7/(1+$A8)^DCF!$B$8:$G$8)+DCF!$G$5*(1+E$5)/($A8-E$5)/(1+$A8)^(DCF!$B$6+5))+DCF!$B$31+DCF!$B$32)/DCF!$B$34)),0)) -> 10.909512 | F8: =((SUMPRODUCT(DCF!$B$7:$G$7/(1+$A8)^DCF!$B$8:$G$8)+DCF!$G$5*(1+F$5)/($A8-F$5)/(1+$A8)^(DCF!$B$6+5))+DCF!$B$31+DCF!$B$32)/(DCF!$B$34+IF((((SUMPRODUCT(DCF!$B$7:$G$7/(1+$A8)^DCF!$B$8:$G$8)+DCF!$G$5*(1+F$5)/($A8-F$5)/(1+$A8)^(DCF!$B$6+5))+DCF!$B$31+DCF!$B$32)/DCF!$B$34)>Inputs!$B$77,Inputs!$B$76*(1-Inputs!$B$77/(((SUMPRODUCT(DCF!$B$7:$G$7/(1+$A8)^DCF!$B$8:$G$8)+DCF!$G$5*(1+F$5)/($A8-F$5)/(1+$A8)^(DCF!$B$6+5))+DCF!$B$31+DCF!$B$32)/DCF!$B$34)),0)) -> 12.521533
A9: 0.095 | B9: =((SUMPRODUCT(DCF!$B$7:$G$7/(1+$A9)^DCF!$B$8:$G$8)+DCF!$G$5*(1+B$5)/($A9-B$5)/(1+$A9)^(DCF!$B$6+5))+DCF!$B$31+DCF!$B$32)/(DCF!$B$34+IF((((SUMPRODUCT(DCF!$B$7:$G$7/(1+$A9)^DCF!$B$8:$G$8)+DCF!$G$5*(1+B$5)/($A9-B$5)/(1+$A9)^(DCF!$B$6+5))+DCF!$B$31+DCF!$B$32)/DCF!$B$34)>Inputs!$B$77,Inputs!$B$76*(1-Inputs!$B$77/(((SUMPRODUCT(DCF!$B$7:$G$7/(1+$A9)^DCF!$B$8:$G$8)+DCF!$G$5*(1+B$5)/($A9-B$5)/(1+$A9)^(DCF!$B$6+5))+DCF!$B$31+DCF!$B$32)/DCF!$B$34)),0)) -> 5.7190155 | C9: =((SUMPRODUCT(DCF!$B$7:$G$7/(1+$A9)^DCF!$B$8:$G$8)+DCF!$G$5*(1+C$5)/($A9-C$5)/(1+$A9)^(DCF!$B$6+5))+DCF!$B$31+DCF!$B$32)/(DCF!$B$34+IF((((SUMPRODUCT(DCF!$B$7:$G$7/(1+$A9)^DCF!$B$8:$G$8)+DCF!$G$5*(1+C$5)/($A9-C$5)/(1+$A9)^(DCF!$B$6+5))+DCF!$B$31+DCF!$B$32)/DCF!$B$34)>Inputs!$B$77,Inputs!$B$76*(1-Inputs!$B$77/(((SUMPRODUCT(DCF!$B$7:$G$7/(1+$A9)^DCF!$B$8:$G$8)+DCF!$G$5*(1+C$5)/($A9-C$5)/(1+$A9)^(DCF!$B$6+5))+DCF!$B$31+DCF!$B$32)/DCF!$B$34)),0)) -> 6.6907928 | D9: =((SUMPRODUCT(DCF!$B$7:$G$7/(1+$A9)^DCF!$B$8:$G$8)+DCF!$G$5*(1+D$5)/($A9-D$5)/(1+$A9)^(DCF!$B$6+5))+DCF!$B$31+DCF!$B$32)/(DCF!$B$34+IF((((SUMPRODUCT(DCF!$B$7:$G$7/(1+$A9)^DCF!$B$8:$G$8)+DCF!$G$5*(1+D$5)/($A9-D$5)/(1+$A9)^(DCF!$B$6+5))+DCF!$B$31+DCF!$B$32)/DCF!$B$34)>Inputs!$B$77,Inputs!$B$76*(1-Inputs!$B$77/(((SUMPRODUCT(DCF!$B$7:$G$7/(1+$A9)^DCF!$B$8:$G$8)+DCF!$G$5*(1+D$5)/($A9-D$5)/(1+$A9)^(DCF!$B$6+5))+DCF!$B$31+DCF!$B$32)/DCF!$B$34)),0)) -> 7.7840423 | E9: =((SUMPRODUCT(DCF!$B$7:$G$7/(1+$A9)^DCF!$B$8:$G$8)+DCF!$G$5*(1+E$5)/($A9-E$5)/(1+$A9)^(DCF!$B$6+5))+DCF!$B$31+DCF!$B$32)/(DCF!$B$34+IF((((SUMPRODUCT(DCF!$B$7:$G$7/(1+$A9)^DCF!$B$8:$G$8)+DCF!$G$5*(1+E$5)/($A9-E$5)/(1+$A9)^(DCF!$B$6+5))+DCF!$B$31+DCF!$B$32)/DCF!$B$34)>Inputs!$B$77,Inputs!$B$76*(1-Inputs!$B$77/(((SUMPRODUCT(DCF!$B$7:$G$7/(1+$A9)^DCF!$B$8:$G$8)+DCF!$G$5*(1+E$5)/($A9-E$5)/(1+$A9)^(DCF!$B$6+5))+DCF!$B$31+DCF!$B$32)/DCF!$B$34)),0)) -> 9.0230584 | F9: =((SUMPRODUCT(DCF!$B$7:$G$7/(1+$A9)^DCF!$B$8:$G$8)+DCF!$G$5*(1+F$5)/($A9-F$5)/(1+$A9)^(DCF!$B$6+5))+DCF!$B$31+DCF!$B$32)/(DCF!$B$34+IF((((SUMPRODUCT(DCF!$B$7:$G$7/(1+$A9)^DCF!$B$8:$G$8)+DCF!$G$5*(1+F$5)/($A9-F$5)/(1+$A9)^(DCF!$B$6+5))+DCF!$B$31+DCF!$B$32)/DCF!$B$34)>Inputs!$B$77,Inputs!$B$76*(1-Inputs!$B$77/(((SUMPRODUCT(DCF!$B$7:$G$7/(1+$A9)^DCF!$B$8:$G$8)+DCF!$G$5*(1+F$5)/($A9-F$5)/(1+$A9)^(DCF!$B$6+5))+DCF!$B$31+DCF!$B$32)/DCF!$B$34)),0)) -> 10.439077
A10: 0.1 | B10: =((SUMPRODUCT(DCF!$B$7:$G$7/(1+$A10)^DCF!$B$8:$G$8)+DCF!$G$5*(1+B$5)/($A10-B$5)/(1+$A10)^(DCF!$B$6+5))+DCF!$B$31+DCF!$B$32)/(DCF!$B$34+IF((((SUMPRODUCT(DCF!$B$7:$G$7/(1+$A10)^DCF!$B$8:$G$8)+DCF!$G$5*(1+B$5)/($A10-B$5)/(1+$A10)^(DCF!$B$6+5))+DCF!$B$31+DCF!$B$32)/DCF!$B$34)>Inputs!$B$77,Inputs!$B$76*(1-Inputs!$B$77/(((SUMPRODUCT(DCF!$B$7:$G$7/(1+$A10)^DCF!$B$8:$G$8)+DCF!$G$5*(1+B$5)/($A10-B$5)/(1+$A10)^(DCF!$B$6+5))+DCF!$B$31+DCF!$B$32)/DCF!$B$34)),0)) -> 4.495342 | C10: =((SUMPRODUCT(DCF!$B$7:$G$7/(1+$A10)^DCF!$B$8:$G$8)+DCF!$G$5*(1+C$5)/($A10-C$5)/(1+$A10)^(DCF!$B$6+5))+DCF!$B$31+DCF!$B$32)/(DCF!$B$34+IF((((SUMPRODUCT(DCF!$B$7:$G$7/(1+$A10)^DCF!$B$8:$G$8)+DCF!$G$5*(1+C$5)/($A10-C$5)/(1+$A10)^(DCF!$B$6+5))+DCF!$B$31+DCF!$B$32)/DCF!$B$34)>Inputs!$B$77,Inputs!$B$76*(1-Inputs!$B$77/(((SUMPRODUCT(DCF!$B$7:$G$7/(1+$A10)^DCF!$B$8:$G$8)+DCF!$G$5*(1+C$5)/($A10-C$5)/(1+$A10)^(DCF!$B$6+5))+DCF!$B$31+DCF!$B$32)/DCF!$B$34)),0)) -> 5.3483869 | D10: =((SUMPRODUCT(DCF!$B$7:$G$7/(1+$A10)^DCF!$B$8:$G$8)+DCF!$G$5*(1+D$5)/($A10-D$5)/(1+$A10)^(DCF!$B$6+5))+DCF!$B$31+DCF!$B$32)/(DCF!$B$34+IF((((SUMPRODUCT(DCF!$B$7:$G$7/(1+$A10)^DCF!$B$8:$G$8)+DCF!$G$5*(1+D$5)/($A10-D$5)/(1+$A10)^(DCF!$B$6+5))+DCF!$B$31+DCF!$B$32)/DCF!$B$34)>Inputs!$B$77,Inputs!$B$76*(1-Inputs!$B$77/(((SUMPRODUCT(DCF!$B$7:$G$7/(1+$A10)^DCF!$B$8:$G$8)+DCF!$G$5*(1+D$5)/($A10-D$5)/(1+$A10)^(DCF!$B$6+5))+DCF!$B$31+DCF!$B$32)/DCF!$B$34)),0)) -> 6.30179 | E10: =((SUMPRODUCT(DCF!$B$7:$G$7/(1+$A10)^DCF!$B$8:$G$8)+DCF!$G$5*(1+E$5)/($A10-E$5)/(1+$A10)^(DCF!$B$6+5))+DCF!$B$31+DCF!$B$32)/(DCF!$B$34+IF((((SUMPRODUCT(DCF!$B$7:$G$7/(1+$A10)^DCF!$B$8:$G$8)+DCF!$G$5*(1+E$5)/($A10-E$5)/(1+$A10)^(DCF!$B$6+5))+DCF!$B$31+DCF!$B$32)/DCF!$B$34)>Inputs!$B$77,Inputs!$B$76*(1-Inputs!$B$77/(((SUMPRODUCT(DCF!$B$7:$G$7/(1+$A10)^DCF!$B$8:$G$8)+DCF!$G$5*(1+E$5)/($A10-E$5)/(1+$A10)^(DCF!$B$6+5))+DCF!$B$31+DCF!$B$32)/DCF!$B$34)),0)) -> 7.3743685 | F10: =((SUMPRODUCT(DCF!$B$7:$G$7/(1+$A10)^DCF!$B$8:$G$8)+DCF!$G$5*(1+F$5)/($A10-F$5)/(1+$A10)^(DCF!$B$6+5))+DCF!$B$31+DCF!$B$32)/(DCF!$B$34+IF((((SUMPRODUCT(DCF!$B$7:$G$7/(1+$A10)^DCF!$B$8:$G$8)+DCF!$G$5*(1+F$5)/($A10-F$5)/(1+$A10)^(DCF!$B$6+5))+DCF!$B$31+DCF!$B$32)/DCF!$B$34)>Inputs!$B$77,Inputs!$B$76*(1-Inputs!$B$77/(((SUMPRODUCT(DCF!$B$7:$G$7/(1+$A10)^DCF!$B$8:$G$8)+DCF!$G$5*(1+F$5)/($A10-F$5)/(1+$A10)^(DCF!$B$6+5))+DCF!$B$31+DCF!$B$32)/DCF!$B$34)),0)) -> 8.5899575
A11: 0.105 | B11: =((SUMPRODUCT(DCF!$B$7:$G$7/(1+$A11)^DCF!$B$8:$G$8)+DCF!$G$5*(1+B$5)/($A11-B$5)/(1+$A11)^(DCF!$B$6+5))+DCF!$B$31+DCF!$B$32)/(DCF!$B$34+IF((((SUMPRODUCT(DCF!$B$7:$G$7/(1+$A11)^DCF!$B$8:$G$8)+DCF!$G$5*(1+B$5)/($A11-B$5)/(1+$A11)^(DCF!$B$6+5))+DCF!$B$31+DCF!$B$32)/DCF!$B$34)>Inputs!$B$77,Inputs!$B$76*(1-Inputs!$B$77/(((SUMPRODUCT(DCF!$B$7:$G$7/(1+$A11)^DCF!$B$8:$G$8)+DCF!$G$5*(1+B$5)/($A11-B$5)/(1+$A11)^(DCF!$B$6+5))+DCF!$B$31+DCF!$B$32)/DCF!$B$34)),0)) -> 3.3956743 | C11: =((SUMPRODUCT(DCF!$B$7:$G$7/(1+$A11)^DCF!$B$8:$G$8)+DCF!$G$5*(1+C$5)/($A11-C$5)/(1+$A11)^(DCF!$B$6+5))+DCF!$B$31+DCF!$B$32)/(DCF!$B$34+IF((((SUMPRODUCT(DCF!$B$7:$G$7/(1+$A11)^DCF!$B$8:$G$8)+DCF!$G$5*(1+C$5)/($A11-C$5)/(1+$A11)^(DCF!$B$6+5))+DCF!$B$31+DCF!$B$32)/DCF!$B$34)>Inputs!$B$77,Inputs!$B$76*(1-Inputs!$B$77/(((SUMPRODUCT(DCF!$B$7:$G$7/(1+$A11)^DCF!$B$8:$G$8)+DCF!$G$5*(1+C$5)/($A11-C$5)/(1+$A11)^(DCF!$B$6+5))+DCF!$B$31+DCF!$B$32)/DCF!$B$34)),0)) -> 4.1489636 | D11: =((SUMPRODUCT(DCF!$B$7:$G$7/(1+$A11)^DCF!$B$8:$G$8)+DCF!$G$5*(1+D$5)/($A11-D$5)/(1+$A11)^(DCF!$B$6+5))+DCF!$B$31+DCF!$B$32)/(DCF!$B$34+IF((((SUMPRODUCT(DCF!$B$7:$G$7/(1+$A11)^DCF!$B$8:$G$8)+DCF!$G$5*(1+D$5)/($A11-D$5)/(1+$A11)^(DCF!$B$6+5))+DCF!$B$31+DCF!$B$32)/DCF!$B$34)>Inputs!$B$77,Inputs!$B$76*(1-Inputs!$B$77/(((SUMPRODUCT(DCF!$B$7:$G$7/(1+$A11)^DCF!$B$8:$G$8)+DCF!$G$5*(1+D$5)/($A11-D$5)/(1+$A11)^(DCF!$B$6+5))+DCF!$B$31+DCF!$B$32)/DCF!$B$34)),0)) -> 4.9859517 | E11: =((SUMPRODUCT(DCF!$B$7:$G$7/(1+$A11)^DCF!$B$8:$G$8)+DCF!$G$5*(1+E$5)/($A11-E$5)/(1+$A11)^(DCF!$B$6+5))+DCF!$B$31+DCF!$B$32)/(DCF!$B$34+IF((((SUMPRODUCT(DCF!$B$7:$G$7/(1+$A11)^DCF!$B$8:$G$8)+DCF!$G$5*(1+E$5)/($A11-E$5)/(1+$A11)^(DCF!$B$6+5))+DCF!$B$31+DCF!$B$32)/DCF!$B$34)>Inputs!$B$77,Inputs!$B$76*(1-Inputs!$B$77/(((SUMPRODUCT(DCF!$B$7:$G$7/(1+$A11)^DCF!$B$8:$G$8)+DCF!$G$5*(1+E$5)/($A11-E$5)/(1+$A11)^(DCF!$B$6+5))+DCF!$B$31+DCF!$B$32)/DCF!$B$34)),0)) -> 5.921409 | F11: =((SUMPRODUCT(DCF!$B$7:$G$7/(1+$A11)^DCF!$B$8:$G$8)+DCF!$G$5*(1+F$5)/($A11-F$5)/(1+$A11)^(DCF!$B$6+5))+DCF!$B$31+DCF!$B$32)/(DCF!$B$34+IF((((SUMPRODUCT(DCF!$B$7:$G$7/(1+$A11)^DCF!$B$8:$G$8)+DCF!$G$5*(1+F$5)/($A11-F$5)/(1+$A11)^(DCF!$B$6+5))+DCF!$B$31+DCF!$B$32)/DCF!$B$34)>Inputs!$B$77,Inputs!$B$76*(1-Inputs!$B$77/(((SUMPRODUCT(DCF!$B$7:$G$7/(1+$A11)^DCF!$B$8:$G$8)+DCF!$G$5*(1+F$5)/($A11-F$5)/(1+$A11)^(DCF!$B$6+5))+DCF!$B$31+DCF!$B$32)/DCF!$B$34)),0)) -> 6.9737985
A12: 0.11 | B12: =((SUMPRODUCT(DCF!$B$7:$G$7/(1+$A12)^DCF!$B$8:$G$8)+DCF!$G$5*(1+B$5)/($A12-B$5)/(1+$A12)^(DCF!$B$6+5))+DCF!$B$31+DCF!$B$32)/(DCF!$B$34+IF((((SUMPRODUCT(DCF!$B$7:$G$7/(1+$A12)^DCF!$B$8:$G$8)+DCF!$G$5*(1+B$5)/($A12-B$5)/(1+$A12)^(DCF!$B$6+5))+DCF!$B$31+DCF!$B$32)/DCF!$B$34)>Inputs!$B$77,Inputs!$B$76*(1-Inputs!$B$77/(((SUMPRODUCT(DCF!$B$7:$G$7/(1+$A12)^DCF!$B$8:$G$8)+DCF!$G$5*(1+B$5)/($A12-B$5)/(1+$A12)^(DCF!$B$6+5))+DCF!$B$31+DCF!$B$32)/DCF!$B$34)),0)) -> 2.4022369 | C12: =((SUMPRODUCT(DCF!$B$7:$G$7/(1+$A12)^DCF!$B$8:$G$8)+DCF!$G$5*(1+C$5)/($A12-C$5)/(1+$A12)^(DCF!$B$6+5))+DCF!$B$31+DCF!$B$32)/(DCF!$B$34+IF((((SUMPRODUCT(DCF!$B$7:$G$7/(1+$A12)^DCF!$B$8:$G$8)+DCF!$G$5*(1+C$5)/($A12-C$5)/(1+$A12)^(DCF!$B$6+5))+DCF!$B$31+DCF!$B$32)/DCF!$B$34)>Inputs!$B$77,Inputs!$B$76*(1-Inputs!$B$77/(((SUMPRODUCT(DCF!$B$7:$G$7/(1+$A12)^DCF!$B$8:$G$8)+DCF!$G$5*(1+C$5)/($A12-C$5)/(1+$A12)^(DCF!$B$6+5))+DCF!$B$31+DCF!$B$32)/DCF!$B$34)),0)) -> 3.071013 | D12: =((SUMPRODUCT(DCF!$B$7:$G$7/(1+$A12)^DCF!$B$8:$G$8)+DCF!$G$5*(1+D$5)/($A12-D$5)/(1+$A12)^(DCF!$B$6+5))+DCF!$B$31+DCF!$B$32)/(DCF!$B$34+IF((((SUMPRODUCT(DCF!$B$7:$G$7/(1+$A12)^DCF!$B$8:$G$8)+DCF!$G$5*(1+D$5)/($A12-D$5)/(1+$A12)^(DCF!$B$6+5))+DCF!$B$31+DCF!$B$32)/DCF!$B$34)>Inputs!$B$77,Inputs!$B$76*(1-Inputs!$B$77/(((SUMPRODUCT(DCF!$B$7:$G$7/(1+$A12)^DCF!$B$8:$G$8)+DCF!$G$5*(1+D$5)/($A12-D$5)/(1+$A12)^(DCF!$B$6+5))+DCF!$B$31+DCF!$B$32)/DCF!$B$34)),0)) -> 3.8101866 | E12: =((SUMPRODUCT(DCF!$B$7:$G$7/(1+$A12)^DCF!$B$8:$G$8)+DCF!$G$5*(1+E$5)/($A12-E$5)/(1+$A12)^(DCF!$B$6+5))+DCF!$B$31+DCF!$B$32)/(DCF!$B$34+IF((((SUMPRODUCT(DCF!$B$7:$G$7/(1+$A12)^DCF!$B$8:$G$8)+DCF!$G$5*(1+E$5)/($A12-E$5)/(1+$A12)^(DCF!$B$6+5))+DCF!$B$31+DCF!$B$32)/DCF!$B$34)>Inputs!$B$77,Inputs!$B$76*(1-Inputs!$B$77/(((SUMPRODUCT(DCF!$B$7:$G$7/(1+$A12)^DCF!$B$8:$G$8)+DCF!$G$5*(1+E$5)/($A12-E$5)/(1+$A12)^(DCF!$B$6+5))+DCF!$B$31+DCF!$B$32)/DCF!$B$34)),0)) -> 4.6314907 | F12: =((SUMPRODUCT(DCF!$B$7:$G$7/(1+$A12)^DCF!$B$8:$G$8)+DCF!$G$5*(1+F$5)/($A12-F$5)/(1+$A12)^(DCF!$B$6+5))+DCF!$B$31+DCF!$B$32)/(DCF!$B$34+IF((((SUMPRODUCT(DCF!$B$7:$G$7/(1+$A12)^DCF!$B$8:$G$8)+DCF!$G$5*(1+F$5)/($A12-F$5)/(1+$A12)^(DCF!$B$6+5))+DCF!$B$31+DCF!$B$32)/DCF!$B$34)>Inputs!$B$77,Inputs!$B$76*(1-Inputs!$B$77/(((SUMPRODUCT(DCF!$B$7:$G$7/(1+$A12)^DCF!$B$8:$G$8)+DCF!$G$5*(1+F$5)/($A12-F$5)/(1+$A12)^(DCF!$B$6+5))+DCF!$B$31+DCF!$B$32)/DCF!$B$34)),0)) -> 5.5494187
A15: Exit multiple method: WACC down, exit EV to EBITDA across. Value per share after warrants, $.
A16: WACC \ multiple | B16: 5 | C16: 6 | D16: 7 | E16: 8 | F16: 9
A17: 0.08 | B17: =((SUMPRODUCT(DCF!$B$7:$G$7/(1+$A17)^DCF!$B$8:$G$8)+B$16*Forecast!$G$13/(1+$A17)^(DCF!$B$6+5))+DCF!$B$31+DCF!$B$32)/(DCF!$B$34+IF((((SUMPRODUCT(DCF!$B$7:$G$7/(1+$A17)^DCF!$B$8:$G$8)+B$16*Forecast!$G$13/(1+$A17)^(DCF!$B$6+5))+DCF!$B$31+DCF!$B$32)/DCF!$B$34)>Inputs!$B$77,Inputs!$B$76*(1-Inputs!$B$77/(((SUMPRODUCT(DCF!$B$7:$G$7/(1+$A17)^DCF!$B$8:$G$8)+B$16*Forecast!$G$13/(1+$A17)^(DCF!$B$6+5))+DCF!$B$31+DCF!$B$32)/DCF!$B$34)),0)) -> 1.6891793 | C17: =((SUMPRODUCT(DCF!$B$7:$G$7/(1+$A17)^DCF!$B$8:$G$8)+C$16*Forecast!$G$13/(1+$A17)^(DCF!$B$6+5))+DCF!$B$31+DCF!$B$32)/(DCF!$B$34+IF((((SUMPRODUCT(DCF!$B$7:$G$7/(1+$A17)^DCF!$B$8:$G$8)+C$16*Forecast!$G$13/(1+$A17)^(DCF!$B$6+5))+DCF!$B$31+DCF!$B$32)/DCF!$B$34)>Inputs!$B$77,Inputs!$B$76*(1-Inputs!$B$77/(((SUMPRODUCT(DCF!$B$7:$G$7/(1+$A17)^DCF!$B$8:$G$8)+C$16*Forecast!$G$13/(1+$A17)^(DCF!$B$6+5))+DCF!$B$31+DCF!$B$32)/DCF!$B$34)),0)) -> 3.8594465 | D17: =((SUMPRODUCT(DCF!$B$7:$G$7/(1+$A17)^DCF!$B$8:$G$8)+D$16*Forecast!$G$13/(1+$A17)^(DCF!$B$6+5))+DCF!$B$31+DCF!$B$32)/(DCF!$B$34+IF((((SUMPRODUCT(DCF!$B$7:$G$7/(1+$A17)^DCF!$B$8:$G$8)+D$16*Forecast!$G$13/(1+$A17)^(DCF!$B$6+5))+DCF!$B$31+DCF!$B$32)/DCF!$B$34)>Inputs!$B$77,Inputs!$B$76*(1-Inputs!$B$77/(((SUMPRODUCT(DCF!$B$7:$G$7/(1+$A17)^DCF!$B$8:$G$8)+D$16*Forecast!$G$13/(1+$A17)^(DCF!$B$6+5))+DCF!$B$31+DCF!$B$32)/DCF!$B$34)),0)) -> 6.0297138 | E17: =((SUMPRODUCT(DCF!$B$7:$G$7/(1+$A17)^DCF!$B$8:$G$8)+E$16*Forecast!$G$13/(1+$A17)^(DCF!$B$6+5))+DCF!$B$31+DCF!$B$32)/(DCF!$B$34+IF((((SUMPRODUCT(DCF!$B$7:$G$7/(1+$A17)^DCF!$B$8:$G$8)+E$16*Forecast!$G$13/(1+$A17)^(DCF!$B$6+5))+DCF!$B$31+DCF!$B$32)/DCF!$B$34)>Inputs!$B$77,Inputs!$B$76*(1-Inputs!$B$77/(((SUMPRODUCT(DCF!$B$7:$G$7/(1+$A17)^DCF!$B$8:$G$8)+E$16*Forecast!$G$13/(1+$A17)^(DCF!$B$6+5))+DCF!$B$31+DCF!$B$32)/DCF!$B$34)),0)) -> 8.1999811 | F17: =((SUMPRODUCT(DCF!$B$7:$G$7/(1+$A17)^DCF!$B$8:$G$8)+F$16*Forecast!$G$13/(1+$A17)^(DCF!$B$6+5))+DCF!$B$31+DCF!$B$32)/(DCF!$B$34+IF((((SUMPRODUCT(DCF!$B$7:$G$7/(1+$A17)^DCF!$B$8:$G$8)+F$16*Forecast!$G$13/(1+$A17)^(DCF!$B$6+5))+DCF!$B$31+DCF!$B$32)/DCF!$B$34)>Inputs!$B$77,Inputs!$B$76*(1-Inputs!$B$77/(((SUMPRODUCT(DCF!$B$7:$G$7/(1+$A17)^DCF!$B$8:$G$8)+F$16*Forecast!$G$13/(1+$A17)^(DCF!$B$6+5))+DCF!$B$31+DCF!$B$32)/DCF!$B$34)),0)) -> 10.370248
A18: 0.085 | B18: =((SUMPRODUCT(DCF!$B$7:$G$7/(1+$A18)^DCF!$B$8:$G$8)+B$16*Forecast!$G$13/(1+$A18)^(DCF!$B$6+5))+DCF!$B$31+DCF!$B$32)/(DCF!$B$34+IF((((SUMPRODUCT(DCF!$B$7:$G$7/(1+$A18)^DCF!$B$8:$G$8)+B$16*Forecast!$G$13/(1+$A18)^(DCF!$B$6+5))+DCF!$B$31+DCF!$B$32)/DCF!$B$34)>Inputs!$B$77,Inputs!$B$76*(1-Inputs!$B$77/(((SUMPRODUCT(DCF!$B$7:$G$7/(1+$A18)^DCF!$B$8:$G$8)+B$16*Forecast!$G$13/(1+$A18)^(DCF!$B$6+5))+DCF!$B$31+DCF!$B$32)/DCF!$B$34)),0)) -> 1.336481 | C18: =((SUMPRODUCT(DCF!$B$7:$G$7/(1+$A18)^DCF!$B$8:$G$8)+C$16*Forecast!$G$13/(1+$A18)^(DCF!$B$6+5))+DCF!$B$31+DCF!$B$32)/(DCF!$B$34+IF((((SUMPRODUCT(DCF!$B$7:$G$7/(1+$A18)^DCF!$B$8:$G$8)+C$16*Forecast!$G$13/(1+$A18)^(DCF!$B$6+5))+DCF!$B$31+DCF!$B$32)/DCF!$B$34)>Inputs!$B$77,Inputs!$B$76*(1-Inputs!$B$77/(((SUMPRODUCT(DCF!$B$7:$G$7/(1+$A18)^DCF!$B$8:$G$8)+C$16*Forecast!$G$13/(1+$A18)^(DCF!$B$6+5))+DCF!$B$31+DCF!$B$32)/DCF!$B$34)),0)) -> 3.4553405 | D18: =((SUMPRODUCT(DCF!$B$7:$G$7/(1+$A18)^DCF!$B$8:$G$8)+D$16*Forecast!$G$13/(1+$A18)^(DCF!$B$6+5))+DCF!$B$31+DCF!$B$32)/(DCF!$B$34+IF((((SUMPRODUCT(DCF!$B$7:$G$7/(1+$A18)^DCF!$B$8:$G$8)+D$16*Forecast!$G$13/(1+$A18)^(DCF!$B$6+5))+DCF!$B$31+DCF!$B$32)/DCF!$B$34)>Inputs!$B$77,Inputs!$B$76*(1-Inputs!$B$77/(((SUMPRODUCT(DCF!$B$7:$G$7/(1+$A18)^DCF!$B$8:$G$8)+D$16*Forecast!$G$13/(1+$A18)^(DCF!$B$6+5))+DCF!$B$31+DCF!$B$32)/DCF!$B$34)),0)) -> 5.5742 | E18: =((SUMPRODUCT(DCF!$B$7:$G$7/(1+$A18)^DCF!$B$8:$G$8)+E$16*Forecast!$G$13/(1+$A18)^(DCF!$B$6+5))+DCF!$B$31+DCF!$B$32)/(DCF!$B$34+IF((((SUMPRODUCT(DCF!$B$7:$G$7/(1+$A18)^DCF!$B$8:$G$8)+E$16*Forecast!$G$13/(1+$A18)^(DCF!$B$6+5))+DCF!$B$31+DCF!$B$32)/DCF!$B$34)>Inputs!$B$77,Inputs!$B$76*(1-Inputs!$B$77/(((SUMPRODUCT(DCF!$B$7:$G$7/(1+$A18)^DCF!$B$8:$G$8)+E$16*Forecast!$G$13/(1+$A18)^(DCF!$B$6+5))+DCF!$B$31+DCF!$B$32)/DCF!$B$34)),0)) -> 7.6930596 | F18: =((SUMPRODUCT(DCF!$B$7:$G$7/(1+$A18)^DCF!$B$8:$G$8)+F$16*Forecast!$G$13/(1+$A18)^(DCF!$B$6+5))+DCF!$B$31+DCF!$B$32)/(DCF!$B$34+IF((((SUMPRODUCT(DCF!$B$7:$G$7/(1+$A18)^DCF!$B$8:$G$8)+F$16*Forecast!$G$13/(1+$A18)^(DCF!$B$6+5))+DCF!$B$31+DCF!$B$32)/DCF!$B$34)>Inputs!$B$77,Inputs!$B$76*(1-Inputs!$B$77/(((SUMPRODUCT(DCF!$B$7:$G$7/(1+$A18)^DCF!$B$8:$G$8)+F$16*Forecast!$G$13/(1+$A18)^(DCF!$B$6+5))+DCF!$B$31+DCF!$B$32)/DCF!$B$34)),0)) -> 9.8119191
A19: 0.09 | B19: =((SUMPRODUCT(DCF!$B$7:$G$7/(1+$A19)^DCF!$B$8:$G$8)+B$16*Forecast!$G$13/(1+$A19)^(DCF!$B$6+5))+DCF!$B$31+DCF!$B$32)/(DCF!$B$34+IF((((SUMPRODUCT(DCF!$B$7:$G$7/(1+$A19)^DCF!$B$8:$G$8)+B$16*Forecast!$G$13/(1+$A19)^(DCF!$B$6+5))+DCF!$B$31+DCF!$B$32)/DCF!$B$34)>Inputs!$B$77,Inputs!$B$76*(1-Inputs!$B$77/(((SUMPRODUCT(DCF!$B$7:$G$7/(1+$A19)^DCF!$B$8:$G$8)+B$16*Forecast!$G$13/(1+$A19)^(DCF!$B$6+5))+DCF!$B$31+DCF!$B$32)/DCF!$B$34)),0)) -> 0.99294921 | C19: =((SUMPRODUCT(DCF!$B$7:$G$7/(1+$A19)^DCF!$B$8:$G$8)+C$16*Forecast!$G$13/(1+$A19)^(DCF!$B$6+5))+DCF!$B$31+DCF!$B$32)/(DCF!$B$34+IF((((SUMPRODUCT(DCF!$B$7:$G$7/(1+$A19)^DCF!$B$8:$G$8)+C$16*Forecast!$G$13/(1+$A19)^(DCF!$B$6+5))+DCF!$B$31+DCF!$B$32)/DCF!$B$34)>Inputs!$B$77,Inputs!$B$76*(1-Inputs!$B$77/(((SUMPRODUCT(DCF!$B$7:$G$7/(1+$A19)^DCF!$B$8:$G$8)+C$16*Forecast!$G$13/(1+$A19)^(DCF!$B$6+5))+DCF!$B$31+DCF!$B$32)/DCF!$B$34)),0)) -> 3.0618468 | D19: =((SUMPRODUCT(DCF!$B$7:$G$7/(1+$A19)^DCF!$B$8:$G$8)+D$16*Forecast!$G$13/(1+$A19)^(DCF!$B$6+5))+DCF!$B$31+DCF!$B$32)/(DCF!$B$34+IF((((SUMPRODUCT(DCF!$B$7:$G$7/(1+$A19)^DCF!$B$8:$G$8)+D$16*Forecast!$G$13/(1+$A19)^(DCF!$B$6+5))+DCF!$B$31+DCF!$B$32)/DCF!$B$34)>Inputs!$B$77,Inputs!$B$76*(1-Inputs!$B$77/(((SUMPRODUCT(DCF!$B$7:$G$7/(1+$A19)^DCF!$B$8:$G$8)+D$16*Forecast!$G$13/(1+$A19)^(DCF!$B$6+5))+DCF!$B$31+DCF!$B$32)/DCF!$B$34)),0)) -> 5.1307443 | E19: =((SUMPRODUCT(DCF!$B$7:$G$7/(1+$A19)^DCF!$B$8:$G$8)+E$16*Forecast!$G$13/(1+$A19)^(DCF!$B$6+5))+DCF!$B$31+DCF!$B$32)/(DCF!$B$34+IF((((SUMPRODUCT(DCF!$B$7:$G$7/(1+$A19)^DCF!$B$8:$G$8)+E$16*Forecast!$G$13/(1+$A19)^(DCF!$B$6+5))+DCF!$B$31+DCF!$B$32)/DCF!$B$34)>Inputs!$B$77,Inputs!$B$76*(1-Inputs!$B$77/(((SUMPRODUCT(DCF!$B$7:$G$7/(1+$A19)^DCF!$B$8:$G$8)+E$16*Forecast!$G$13/(1+$A19)^(DCF!$B$6+5))+DCF!$B$31+DCF!$B$32)/DCF!$B$34)),0)) -> 7.1996419 | F19: =((SUMPRODUCT(DCF!$B$7:$G$7/(1+$A19)^DCF!$B$8:$G$8)+F$16*Forecast!$G$13/(1+$A19)^(DCF!$B$6+5))+DCF!$B$31+DCF!$B$32)/(DCF!$B$34+IF((((SUMPRODUCT(DCF!$B$7:$G$7/(1+$A19)^DCF!$B$8:$G$8)+F$16*Forecast!$G$13/(1+$A19)^(DCF!$B$6+5))+DCF!$B$31+DCF!$B$32)/DCF!$B$34)>Inputs!$B$77,Inputs!$B$76*(1-Inputs!$B$77/(((SUMPRODUCT(DCF!$B$7:$G$7/(1+$A19)^DCF!$B$8:$G$8)+F$16*Forecast!$G$13/(1+$A19)^(DCF!$B$6+5))+DCF!$B$31+DCF!$B$32)/DCF!$B$34)),0)) -> 9.2685394
A20: 0.095 | B20: =((SUMPRODUCT(DCF!$B$7:$G$7/(1+$A20)^DCF!$B$8:$G$8)+B$16*Forecast!$G$13/(1+$A20)^(DCF!$B$6+5))+DCF!$B$31+DCF!$B$32)/(DCF!$B$34+IF((((SUMPRODUCT(DCF!$B$7:$G$7/(1+$A20)^DCF!$B$8:$G$8)+B$16*Forecast!$G$13/(1+$A20)^(DCF!$B$6+5))+DCF!$B$31+DCF!$B$32)/DCF!$B$34)>Inputs!$B$77,Inputs!$B$76*(1-Inputs!$B$77/(((SUMPRODUCT(DCF!$B$7:$G$7/(1+$A20)^DCF!$B$8:$G$8)+B$16*Forecast!$G$13/(1+$A20)^(DCF!$B$6+5))+DCF!$B$31+DCF!$B$32)/DCF!$B$34)),0)) -> 0.65829845 | C20: =((SUMPRODUCT(DCF!$B$7:$G$7/(1+$A20)^DCF!$B$8:$G$8)+C$16*Forecast!$G$13/(1+$A20)^(DCF!$B$6+5))+DCF!$B$31+DCF!$B$32)/(DCF!$B$34+IF((((SUMPRODUCT(DCF!$B$7:$G$7/(1+$A20)^DCF!$B$8:$G$8)+C$16*Forecast!$G$13/(1+$A20)^(DCF!$B$6+5))+DCF!$B$31+DCF!$B$32)/DCF!$B$34)>Inputs!$B$77,Inputs!$B$76*(1-Inputs!$B$77/(((SUMPRODUCT(DCF!$B$7:$G$7/(1+$A20)^DCF!$B$8:$G$8)+C$16*Forecast!$G$13/(1+$A20)^(DCF!$B$6+5))+DCF!$B$31+DCF!$B$32)/DCF!$B$34)),0)) -> 2.6786327 | D20: =((SUMPRODUCT(DCF!$B$7:$G$7/(1+$A20)^DCF!$B$8:$G$8)+D$16*Forecast!$G$13/(1+$A20)^(DCF!$B$6+5))+DCF!$B$31+DCF!$B$32)/(DCF!$B$34+IF((((SUMPRODUCT(DCF!$B$7:$G$7/(1+$A20)^DCF!$B$8:$G$8)+D$16*Forecast!$G$13/(1+$A20)^(DCF!$B$6+5))+DCF!$B$31+DCF!$B$32)/DCF!$B$34)>Inputs!$B$77,Inputs!$B$76*(1-Inputs!$B$77/(((SUMPRODUCT(DCF!$B$7:$G$7/(1+$A20)^DCF!$B$8:$G$8)+D$16*Forecast!$G$13/(1+$A20)^(DCF!$B$6+5))+DCF!$B$31+DCF!$B$32)/DCF!$B$34)),0)) -> 4.698967 | E20: =((SUMPRODUCT(DCF!$B$7:$G$7/(1+$A20)^DCF!$B$8:$G$8)+E$16*Forecast!$G$13/(1+$A20)^(DCF!$B$6+5))+DCF!$B$31+DCF!$B$32)/(DCF!$B$34+IF((((SUMPRODUCT(DCF!$B$7:$G$7/(1+$A20)^DCF!$B$8:$G$8)+E$16*Forecast!$G$13/(1+$A20)^(DCF!$B$6+5))+DCF!$B$31+DCF!$B$32)/DCF!$B$34)>Inputs!$B$77,Inputs!$B$76*(1-Inputs!$B$77/(((SUMPRODUCT(DCF!$B$7:$G$7/(1+$A20)^DCF!$B$8:$G$8)+E$16*Forecast!$G$13/(1+$A20)^(DCF!$B$6+5))+DCF!$B$31+DCF!$B$32)/DCF!$B$34)),0)) -> 6.7193013 | F20: =((SUMPRODUCT(DCF!$B$7:$G$7/(1+$A20)^DCF!$B$8:$G$8)+F$16*Forecast!$G$13/(1+$A20)^(DCF!$B$6+5))+DCF!$B$31+DCF!$B$32)/(DCF!$B$34+IF((((SUMPRODUCT(DCF!$B$7:$G$7/(1+$A20)^DCF!$B$8:$G$8)+F$16*Forecast!$G$13/(1+$A20)^(DCF!$B$6+5))+DCF!$B$31+DCF!$B$32)/DCF!$B$34)>Inputs!$B$77,Inputs!$B$76*(1-Inputs!$B$77/(((SUMPRODUCT(DCF!$B$7:$G$7/(1+$A20)^DCF!$B$8:$G$8)+F$16*Forecast!$G$13/(1+$A20)^(DCF!$B$6+5))+DCF!$B$31+DCF!$B$32)/DCF!$B$34)),0)) -> 8.7396356
A21: 0.1 | B21: =((SUMPRODUCT(DCF!$B$7:$G$7/(1+$A21)^DCF!$B$8:$G$8)+B$16*Forecast!$G$13/(1+$A21)^(DCF!$B$6+5))+DCF!$B$31+DCF!$B$32)/(DCF!$B$34+IF((((SUMPRODUCT(DCF!$B$7:$G$7/(1+$A21)^DCF!$B$8:$G$8)+B$16*Forecast!$G$13/(1+$A21)^(DCF!$B$6+5))+DCF!$B$31+DCF!$B$32)/DCF!$B$34)>Inputs!$B$77,Inputs!$B$76*(1-Inputs!$B$77/(((SUMPRODUCT(DCF!$B$7:$G$7/(1+$A21)^DCF!$B$8:$G$8)+B$16*Forecast!$G$13/(1+$A21)^(DCF!$B$6+5))+DCF!$B$31+DCF!$B$32)/DCF!$B$34)),0)) -> 0.3322533 | C21: =((SUMPRODUCT(DCF!$B$7:$G$7/(1+$A21)^DCF!$B$8:$G$8)+C$16*Forecast!$G$13/(1+$A21)^(DCF!$B$6+5))+DCF!$B$31+DCF!$B$32)/(DCF!$B$34+IF((((SUMPRODUCT(DCF!$B$7:$G$7/(1+$A21)^DCF!$B$8:$G$8)+C$16*Forecast!$G$13/(1+$A21)^(DCF!$B$6+5))+DCF!$B$31+DCF!$B$32)/DCF!$B$34)>Inputs!$B$77,Inputs!$B$76*(1-Inputs!$B$77/(((SUMPRODUCT(DCF!$B$7:$G$7/(1+$A21)^DCF!$B$8:$G$8)+C$16*Forecast!$G$13/(1+$A21)^(DCF!$B$6+5))+DCF!$B$31+DCF!$B$32)/DCF!$B$34)),0)) -> 2.3053777 | D21: =((SUMPRODUCT(DCF!$B$7:$G$7/(1+$A21)^DCF!$B$8:$G$8)+D$16*Forecast!$G$13/(1+$A21)^(DCF!$B$6+5))+DCF!$B$31+DCF!$B$32)/(DCF!$B$34+IF((((SUMPRODUCT(DCF!$B$7:$G$7/(1+$A21)^DCF!$B$8:$G$8)+D$16*Forecast!$G$13/(1+$A21)^(DCF!$B$6+5))+DCF!$B$31+DCF!$B$32)/DCF!$B$34)>Inputs!$B$77,Inputs!$B$76*(1-Inputs!$B$77/(((SUMPRODUCT(DCF!$B$7:$G$7/(1+$A21)^DCF!$B$8:$G$8)+D$16*Forecast!$G$13/(1+$A21)^(DCF!$B$6+5))+DCF!$B$31+DCF!$B$32)/DCF!$B$34)),0)) -> 4.2785022 | E21: =((SUMPRODUCT(DCF!$B$7:$G$7/(1+$A21)^DCF!$B$8:$G$8)+E$16*Forecast!$G$13/(1+$A21)^(DCF!$B$6+5))+DCF!$B$31+DCF!$B$32)/(DCF!$B$34+IF((((SUMPRODUCT(DCF!$B$7:$G$7/(1+$A21)^DCF!$B$8:$G$8)+E$16*Forecast!$G$13/(1+$A21)^(DCF!$B$6+5))+DCF!$B$31+DCF!$B$32)/DCF!$B$34)>Inputs!$B$77,Inputs!$B$76*(1-Inputs!$B$77/(((SUMPRODUCT(DCF!$B$7:$G$7/(1+$A21)^DCF!$B$8:$G$8)+E$16*Forecast!$G$13/(1+$A21)^(DCF!$B$6+5))+DCF!$B$31+DCF!$B$32)/DCF!$B$34)),0)) -> 6.2516266 | F21: =((SUMPRODUCT(DCF!$B$7:$G$7/(1+$A21)^DCF!$B$8:$G$8)+F$16*Forecast!$G$13/(1+$A21)^(DCF!$B$6+5))+DCF!$B$31+DCF!$B$32)/(DCF!$B$34+IF((((SUMPRODUCT(DCF!$B$7:$G$7/(1+$A21)^DCF!$B$8:$G$8)+F$16*Forecast!$G$13/(1+$A21)^(DCF!$B$6+5))+DCF!$B$31+DCF!$B$32)/DCF!$B$34)>Inputs!$B$77,Inputs!$B$76*(1-Inputs!$B$77/(((SUMPRODUCT(DCF!$B$7:$G$7/(1+$A21)^DCF!$B$8:$G$8)+F$16*Forecast!$G$13/(1+$A21)^(DCF!$B$6+5))+DCF!$B$31+DCF!$B$32)/DCF!$B$34)),0)) -> 8.224751
A22: 0.105 | B22: =((SUMPRODUCT(DCF!$B$7:$G$7/(1+$A22)^DCF!$B$8:$G$8)+B$16*Forecast!$G$13/(1+$A22)^(DCF!$B$6+5))+DCF!$B$31+DCF!$B$32)/(DCF!$B$34+IF((((SUMPRODUCT(DCF!$B$7:$G$7/(1+$A22)^DCF!$B$8:$G$8)+B$16*Forecast!$G$13/(1+$A22)^(DCF!$B$6+5))+DCF!$B$31+DCF!$B$32)/DCF!$B$34)>Inputs!$B$77,Inputs!$B$76*(1-Inputs!$B$77/(((SUMPRODUCT(DCF!$B$7:$G$7/(1+$A22)^DCF!$B$8:$G$8)+B$16*Forecast!$G$13/(1+$A22)^(DCF!$B$6+5))+DCF!$B$31+DCF!$B$32)/DCF!$B$34)),0)) -> 0.014548237 | C22: =((SUMPRODUCT(DCF!$B$7:$G$7/(1+$A22)^DCF!$B$8:$G$8)+C$16*Forecast!$G$13/(1+$A22)^(DCF!$B$6+5))+DCF!$B$31+DCF!$B$32)/(DCF!$B$34+IF((((SUMPRODUCT(DCF!$B$7:$G$7/(1+$A22)^DCF!$B$8:$G$8)+C$16*Forecast!$G$13/(1+$A22)^(DCF!$B$6+5))+DCF!$B$31+DCF!$B$32)/DCF!$B$34)>Inputs!$B$77,Inputs!$B$76*(1-Inputs!$B$77/(((SUMPRODUCT(DCF!$B$7:$G$7/(1+$A22)^DCF!$B$8:$G$8)+C$16*Forecast!$G$13/(1+$A22)^(DCF!$B$6+5))+DCF!$B$31+DCF!$B$32)/DCF!$B$34)),0)) -> 1.9417726 | D22: =((SUMPRODUCT(DCF!$B$7:$G$7/(1+$A22)^DCF!$B$8:$G$8)+D$16*Forecast!$G$13/(1+$A22)^(DCF!$B$6+5))+DCF!$B$31+DCF!$B$32)/(DCF!$B$34+IF((((SUMPRODUCT(DCF!$B$7:$G$7/(1+$A22)^DCF!$B$8:$G$8)+D$16*Forecast!$G$13/(1+$A22)^(DCF!$B$6+5))+DCF!$B$31+DCF!$B$32)/DCF!$B$34)>Inputs!$B$77,Inputs!$B$76*(1-Inputs!$B$77/(((SUMPRODUCT(DCF!$B$7:$G$7/(1+$A22)^DCF!$B$8:$G$8)+D$16*Forecast!$G$13/(1+$A22)^(DCF!$B$6+5))+DCF!$B$31+DCF!$B$32)/DCF!$B$34)),0)) -> 3.8689971 | E22: =((SUMPRODUCT(DCF!$B$7:$G$7/(1+$A22)^DCF!$B$8:$G$8)+E$16*Forecast!$G$13/(1+$A22)^(DCF!$B$6+5))+DCF!$B$31+DCF!$B$32)/(DCF!$B$34+IF((((SUMPRODUCT(DCF!$B$7:$G$7/(1+$A22)^DCF!$B$8:$G$8)+E$16*Forecast!$G$13/(1+$A22)^(DCF!$B$6+5))+DCF!$B$31+DCF!$B$32)/DCF!$B$34)>Inputs!$B$77,Inputs!$B$76*(1-Inputs!$B$77/(((SUMPRODUCT(DCF!$B$7:$G$7/(1+$A22)^DCF!$B$8:$G$8)+E$16*Forecast!$G$13/(1+$A22)^(DCF!$B$6+5))+DCF!$B$31+DCF!$B$32)/DCF!$B$34)),0)) -> 5.7962215 | F22: =((SUMPRODUCT(DCF!$B$7:$G$7/(1+$A22)^DCF!$B$8:$G$8)+F$16*Forecast!$G$13/(1+$A22)^(DCF!$B$6+5))+DCF!$B$31+DCF!$B$32)/(DCF!$B$34+IF((((SUMPRODUCT(DCF!$B$7:$G$7/(1+$A22)^DCF!$B$8:$G$8)+F$16*Forecast!$G$13/(1+$A22)^(DCF!$B$6+5))+DCF!$B$31+DCF!$B$32)/DCF!$B$34)>Inputs!$B$77,Inputs!$B$76*(1-Inputs!$B$77/(((SUMPRODUCT(DCF!$B$7:$G$7/(1+$A22)^DCF!$B$8:$G$8)+F$16*Forecast!$G$13/(1+$A22)^(DCF!$B$6+5))+DCF!$B$31+DCF!$B$32)/DCF!$B$34)),0)) -> 7.7234459
A23: 0.11 | B23: =((SUMPRODUCT(DCF!$B$7:$G$7/(1+$A23)^DCF!$B$8:$G$8)+B$16*Forecast!$G$13/(1+$A23)^(DCF!$B$6+5))+DCF!$B$31+DCF!$B$32)/(DCF!$B$34+IF((((SUMPRODUCT(DCF!$B$7:$G$7/(1+$A23)^DCF!$B$8:$G$8)+B$16*Forecast!$G$13/(1+$A23)^(DCF!$B$6+5))+DCF!$B$31+DCF!$B$32)/DCF!$B$34)>Inputs!$B$77,Inputs!$B$76*(1-Inputs!$B$77/(((SUMPRODUCT(DCF!$B$7:$G$7/(1+$A23)^DCF!$B$8:$G$8)+B$16*Forecast!$G$13/(1+$A23)^(DCF!$B$6+5))+DCF!$B$31+DCF!$B$32)/DCF!$B$34)),0)) -> -0.29507281 | C23: =((SUMPRODUCT(DCF!$B$7:$G$7/(1+$A23)^DCF!$B$8:$G$8)+C$16*Forecast!$G$13/(1+$A23)^(DCF!$B$6+5))+DCF!$B$31+DCF!$B$32)/(DCF!$B$34+IF((((SUMPRODUCT(DCF!$B$7:$G$7/(1+$A23)^DCF!$B$8:$G$8)+C$16*Forecast!$G$13/(1+$A23)^(DCF!$B$6+5))+DCF!$B$31+DCF!$B$32)/DCF!$B$34)>Inputs!$B$77,Inputs!$B$76*(1-Inputs!$B$77/(((SUMPRODUCT(DCF!$B$7:$G$7/(1+$A23)^DCF!$B$8:$G$8)+C$16*Forecast!$G$13/(1+$A23)^(DCF!$B$6+5))+DCF!$B$31+DCF!$B$32)/DCF!$B$34)),0)) -> 1.5875194 | D23: =((SUMPRODUCT(DCF!$B$7:$G$7/(1+$A23)^DCF!$B$8:$G$8)+D$16*Forecast!$G$13/(1+$A23)^(DCF!$B$6+5))+DCF!$B$31+DCF!$B$32)/(DCF!$B$34+IF((((SUMPRODUCT(DCF!$B$7:$G$7/(1+$A23)^DCF!$B$8:$G$8)+D$16*Forecast!$G$13/(1+$A23)^(DCF!$B$6+5))+DCF!$B$31+DCF!$B$32)/DCF!$B$34)>Inputs!$B$77,Inputs!$B$76*(1-Inputs!$B$77/(((SUMPRODUCT(DCF!$B$7:$G$7/(1+$A23)^DCF!$B$8:$G$8)+D$16*Forecast!$G$13/(1+$A23)^(DCF!$B$6+5))+DCF!$B$31+DCF!$B$32)/DCF!$B$34)),0)) -> 3.4701116 | E23: =((SUMPRODUCT(DCF!$B$7:$G$7/(1+$A23)^DCF!$B$8:$G$8)+E$16*Forecast!$G$13/(1+$A23)^(DCF!$B$6+5))+DCF!$B$31+DCF!$B$32)/(DCF!$B$34+IF((((SUMPRODUCT(DCF!$B$7:$G$7/(1+$A23)^DCF!$B$8:$G$8)+E$16*Forecast!$G$13/(1+$A23)^(DCF!$B$6+5))+DCF!$B$31+DCF!$B$32)/DCF!$B$34)>Inputs!$B$77,Inputs!$B$76*(1-Inputs!$B$77/(((SUMPRODUCT(DCF!$B$7:$G$7/(1+$A23)^DCF!$B$8:$G$8)+E$16*Forecast!$G$13/(1+$A23)^(DCF!$B$6+5))+DCF!$B$31+DCF!$B$32)/DCF!$B$34)),0)) -> 5.3527037 | F23: =((SUMPRODUCT(DCF!$B$7:$G$7/(1+$A23)^DCF!$B$8:$G$8)+F$16*Forecast!$G$13/(1+$A23)^(DCF!$B$6+5))+DCF!$B$31+DCF!$B$32)/(DCF!$B$34+IF((((SUMPRODUCT(DCF!$B$7:$G$7/(1+$A23)^DCF!$B$8:$G$8)+F$16*Forecast!$G$13/(1+$A23)^(DCF!$B$6+5))+DCF!$B$31+DCF!$B$32)/DCF!$B$34)>Inputs!$B$77,Inputs!$B$76*(1-Inputs!$B$77/(((SUMPRODUCT(DCF!$B$7:$G$7/(1+$A23)^DCF!$B$8:$G$8)+F$16*Forecast!$G$13/(1+$A23)^(DCF!$B$6+5))+DCF!$B$31+DCF!$B$32)/DCF!$B$34)),0)) -> 7.2352959
A26: Scenario summary. Change Inputs!C5 to see each scenario live; the three rows below are the values as built.
A27: Scenario | B27: 2031E EBITDA | C27: $ per share, perpetuity | D27: $ per share, exit
A28: Base | B28: 16308 | C28: 8.8 | D28: 4.97
A29: Bear | B29: 11039 | C29: -0.33 | D29: -2.1
A30: Management | B30: 18899 | C30: 13.72 | D30: 8.8
A32: Market price for reference | B32: =Inputs!$B$74 -> 7.77
A33: Street price target range, context only: low 2.00, median 8.35, high 13.74 [14]

Sheet Sources
A1: Sources
A2: Skydance Corporation (NYSE: SKYD), pro forma for Warner Bros. Discovery. USD millions unless labelled. Blue = input, black = formula, green = link to another sheet.
A4: # | B4: Source
A5: 1 | B5: Paramount Skydance Corp, Form 10-K for fiscal 2025. https://www.sec.gov/Archives/edgar/data/2041610/000204161026000011/psky-20251231.htm
A6: 2 | B6: Paramount Skydance Corp, Form 10-Q for the quarter ended June 30, 2026. https://www.sec.gov/Archives/edgar/data/0002041610/000204161026000054/psky-20260630.htm
A7: 3 | B7: Paramount Skydance Corp, Q4 and full year 2025 earnings release, February 2026. https://www.sec.gov/Archives/edgar/data/2041610/000204161026000008/ex99_q425.htm
A8: 4 | B8: Paramount Skydance Corp, Q1 2026 earnings release, May 2026. https://www.sec.gov/Archives/edgar/data/0002041610/000204161026000022/ex99_q126.htm
A9: 5 | B9: Paramount Skydance Corp, Q2 2026 earnings release, August 4, 2026. https://www.sec.gov/Archives/edgar/data/0002041610/000204161026000052/ex99_q226.htm
A10: 6 | B10: Paramount Skydance Corp, Form 8-K filed July 31, 2026, merger terms, financing and pro forma financials. https://ir.paramount.com/node/73246/html
A11: 7 | B11: Warner Bros. Discovery, Form 8-K on completion of the merger, October 2026. https://www.sec.gov/Archives/edgar/data/0001437107/000119312526415055/d200872d8k.htm
A12: 8 | B12: Skydance Corp, Form 8-K dated October 9, 2026: warrants, exchange and tender results, second lien notes. https://www.sec.gov/Archives/edgar/data/0002041610/000110465926115294/tm2626659d12_8k.htm
A13: 9 | B13: Paramount Global, Q4 and full year 2023 earnings release, February 2024. https://www.sec.gov/Archives/edgar/data/813828/000119312524050664/d757936dex99.htm
A14: 10 | B14: Debtwire, ION Analytics, Skydance Corporation credit report, October 2026. https://ionanalytics.com/insights/debtwire/skydance-corporation-synergies-alone-wont-hit-leverage-targets-credit-report/
A15: 11 | B15: TheWrap, Wall Street banks wrap up $52 billion debt sale, October 2, 2026. https://www.thewrap.com/industry-news/business/paramount-warner-bros-merger-52-billion-debt-sale-completed/
A16: 12 | B16: Cord Cutters News, Paramount completes Warner Bros. Discovery acquisition, October 6, 2026. https://cordcuttersnews.com/its-done-paramount-completes-warner-bros-discovery-acquisition-launches-combined-company-as-skydance/
... A22: 18 | B22: Warner Bros. Discovery, Q2 2026 earnings release, Form 8-K, August 2026. https://www.sec.gov/Archives/edgar/data/0001437107/000143710726000072/wbd2q26earningsrelease08.htm
B24: Analyst inputs with no source are labelled as such on the Inputs and WACC sheets. Nothing in this workbook comes from a Bloomberg Terminal or from any employer.
